Workbook

Sheet Assumptions
A1: F1R3FLY — Sharding Economics Model
A2: Assumptions & levers. All downstream tabs are formula-linked to this sheet.
A3: Legend: | B3: Blue = input / lever | C3: Black = formula | D3: Green = cross-sheet link
A5: INFRASTRUCTURE (OCI list prices, Q1–Q2 2026)
A6: Nodes per shard | B6: 10 | C6: nodes
A7: Cores (OCPU) per node | B7: 16 | C7: OCPU
A8: Memory per node | B8: 16 | C8: GB
A9: Storage per node | B9: 2 | C9: TB
A10: Hours per month | B10: 730 | C10: h
A11: Compute rate | B11: 0.025 | C11: $/OCPU-hr
A12: Memory rate | B12: 0.0015 | C12: $/GB-hr
A13: Block storage rate | B13: 0.0255 | C13: $/GB-mo
A14: Ops / overhead | B14: 0.15 | C14: %
A15: Per-residual footprint | B15: 1 | C15: KB
A16: Residuals per deploy | B16: 5 | C16: count
A18: CAPACITY & PACKING
A19: Dense capacity per shard | B19: 30000000 | C19: tx/mo
A20: Headroom capacity per shard | B20: 20000000 | C20: tx/mo
A21: Hot slots per shard | B21: =B6*B8*1000000000/(B15*1000) -> 160000000 | C21: slots
A23: ADVERTISING
A24: Display CPM | B24: 3 | C24: $/1000 impr
A25: Per-impression value | B25: =B24/1000 -> 0.003 | C25: $/impr
A27: SECTOR FEES (r_tx, blended $/transaction)
A28: AI | B28: 0.01 | C28: $/tx
A29: Fintech | B29: 0.25 | C29: $/tx
A30: Music | B30: 0.0003 | C30: $/play
A31: Medical — $/patient/month (R) | B31: 1 | C31: $/pt-mo
A32: Medical — tx/patient/month (τ) | B32: 50 | C32: tx/pt-mo
A33: Medical — implied $/tx | B33: =B31/B32 -> 0.02 | C33: $/tx
A35: COMPLIANCE MULTIPLIERS
A36: AI | B36: 1.2 | C36: x
A37: Music | B37: 1 | C37: x
A38: Biotech | B38: 1.5 | C38: x
A39: Fintech | B39: 2.5 | C39: x
A40: Medical | B40: 4 | C40: x
A42: BANDWIDTH (OCI egress; set to 0 to model reported free-egress)
A43: Internet egress | B43: 0.0085 | C43: $/GB
A44: Inter-region egress | B44: 0.005 | C44: $/GB
A45: CDN / edge egress | B45: 0.04 | C45: $/GB
A46: Free egress tier | B46: 10 | C46: TB/mo
...

Sheet Rent Cost Model
A1: Rent — Monthly Network Cost of One Shard
A2: Builds the all-in monthly cost C that rent amortizes. Linked to Assumptions.
A4: Resource | B4: Quantity | C4: Unit price ($) | D4: Monthly cost ($)
A5: Compute (OCPU) | B5: =Assumptions!$B$6*Assumptions!$B$7 -> 160 | C5: =Assumptions!$B$11 -> 0.025 | D5: =B5*C5*Assumptions!$B$10 -> 2920
A6: Memory (GB) | B6: =Assumptions!$B$6*Assumptions!$B$8 -> 160 | C6: =Assumptions!$B$12 -> 0.0015 | D6: =B6*C6*Assumptions!$B$10 -> 175.2
A7: Block storage (GB) | B7: =Assumptions!$B$6*Assumptions!$B$9*1024 -> 20480 | C7: =Assumptions!$B$13 -> 0.0255 | D7: =B7*C7 -> 522.24
A8: Egress (<=10TB free) | B8: 0 | C8: 0 | D8: 0
A9: Subtotal | D9: =SUM(D5:D8) -> 3617.44
A10: Ops / overhead | C10: =Assumptions!$B$14 -> 0.15 | D10: =D9*C10 -> 542.616
A11: All-in monthly cost C | D11: =D9+D10 -> 4160.056
A13: Per-payload cost at dense packing | D13: =D11/Assumptions!$B$19 -> 0.00013866853

Sheet Rent Density
A1: Rent — Tenant Density, Base Rent & Split Threshold
A2: Standing tenants and base rent versus client deployment rate.
A4: Deploys / day | B4: Standing tenants | C4: Hot-table occupancy | D4: Base rent ($/tenant-mo)
A5: 100 | B5: =A5*30*Assumptions!$B$16 -> 15000 | C5: =B5/Assumptions!$B$21 -> 9.375e-05 | D5: ='Rent Cost Model'!$D$11/B5 -> 0.27733707
A6: 1000 | B6: =A6*30*Assumptions!$B$16 -> 150000 | C6: =B6/Assumptions!$B$21 -> 0.0009375 | D6: ='Rent Cost Model'!$D$11/B6 -> 0.027733707
A7: 10000 | B7: =A7*30*Assumptions!$B$16 -> 1500000 | C7: =B7/Assumptions!$B$21 -> 0.009375 | D7: ='Rent Cost Model'!$D$11/B7 -> 0.0027733707
A8: 100000 | B8: =A8*30*Assumptions!$B$16 -> 15000000 | C8: =B8/Assumptions!$B$21 -> 0.09375 | D8: ='Rent Cost Model'!$D$11/B8 -> 0.00027733707
A9: 1000000 | B9: =A9*30*Assumptions!$B$16 -> 150000000 | C9: =B9/Assumptions!$B$21 -> 0.9375 | D9: ='Rent Cost Model'!$D$11/B9 -> 2.7733707e-05
A11: SPLIT THRESHOLD (when a shard should divide)
A12: Split overhead K (probe-equiv) | B12: 50
A13: Conventional open addressing α* | B13: =1-1/B12 -> 0.98
A14: Elastic constant C | B14: 1
A15: Elastic hashing α* (FKK 2025) | B15: =1-0.5*EXP(-B12/B14) -> 1

Sheet Rent Solvency
A1: Rent — Solvency Grid
A2: Net rent = base rent(D) − access fee. Green = self-sustaining (surplus).
A4: Deploys/day \ fee | B4: 0 | C4: 0.0001 | D4: 0.001 | E4: 0.01 | F4: 0.1
A5: 100 | B5: ='Rent Density'!$D$5-B$4 -> 0.27733707 | C5: ='Rent Density'!$D$5-C$4 -> 0.27723707 | D5: ='Rent Density'!$D$5-D$4 -> 0.27633707 | E5: ='Rent Density'!$D$5-E$4 -> 0.26733707 | F5: ='Rent Density'!$D$5-F$4 -> 0.17733707
A6: 1000 | B6: ='Rent Density'!$D$6-B$4 -> 0.027733707 | C6: ='Rent Density'!$D$6-C$4 -> 0.027633707 | D6: ='Rent Density'!$D$6-D$4 -> 0.026733707 | E6: ='Rent Density'!$D$6-E$4 -> 0.017733707 | F6: ='Rent Density'!$D$6-F$4 -> -0.072266293
A7: 10000 | B7: ='Rent Density'!$D$7-B$4 -> 0.0027733707 | C7: ='Rent Density'!$D$7-C$4 -> 0.0026733707 | D7: ='Rent Density'!$D$7-D$4 -> 0.0017733707 | E7: ='Rent Density'!$D$7-E$4 -> -0.0072266293 | F7: ='Rent Density'!$D$7-F$4 -> -0.097226629
A8: 100000 | B8: ='Rent Density'!$D$8-B$4 -> 0.00027733707 | C8: ='Rent Density'!$D$8-C$4 -> 0.00017733707 | D8: ='Rent Density'!$D$8-D$4 -> -0.00072266293 | E8: ='Rent Density'!$D$8-E$4 -> -0.0097226629 | F8: ='Rent Density'!$D$8-F$4 -> -0.099722663
A9: 1000000 | B9: ='Rent Density'!$D$9-B$4 -> 2.7733707e-05 | C9: ='Rent Density'!$D$9-C$4 -> -7.2266293e-05 | D9: ='Rent Density'!$D$9-D$4 -> -0.00097226629 | E9: ='Rent Density'!$D$9-E$4 -> -0.0099722663 | F9: ='Rent Density'!$D$9-F$4 -> -0.099972266

Sheet AI
A1: AI (ASI Alliance) — the growth engine
A2: Unbounded, machine-generated volume. Anchors the rollout.
A4: PARAMETERS
A5: Fee r_tx ($/tx) | B5: =Assumptions!$B$28 -> 0.01
A6: Compliance multiplier | B6: =Assumptions!$B$36 -> 1.2
A7: All-in cost C ($/shard-mo) | B7: ='Rent Cost Model'!$D$11 -> 4160.056
A8: Effective cost C_eff ($/shard-mo) | B8: =B6*B7 -> 4992.0672
A9: Dense capacity (tx/shard-mo) | B9: =Assumptions!$B$19 -> 30000000
A10: Transactions per agent / month | B10: 10000
A11: Break-even traffic (tx/mo) | B11: =B8/B5 -> 499206.72
A12: Break-even load (% of shard) | B12: =B11/B9 -> 0.016640224
A14: Year | B14: Agents | C14: Monthly tx | D14: Shards | E14: Cost ($) | F14: Revenue ($) | G14: Margin
A15: 1 | B15: 100 | C15: =B15*$B$10 -> 1000000 | D15: =CEILING(C15/$B$9,1) -> 1 | E15: =D15*$B$8 -> 4992.0672 | F15: =C15*$B$5 -> 10000 | G15: =F15/E15 -> 2.0031782
A16: 2 | B16: 1000 | C16: =B16*$B$10 -> 10000000 | D16: =CEILING(C16/$B$9,1) -> 1 | E16: =D16*$B$8 -> 4992.0672 | F16: =C16*$B$5 -> 100000 | G16: =F16/E16 -> 20.031782
A17: 3 | B17: 10000 | C17: =B17*$B$10 -> 100000000 | D17: =CEILING(C17/$B$9,1) -> 4 | E17: =D17*$B$8 -> 19968.269 | F17: =C17*$B$5 -> 1000000 | G17: =F17/E17 -> 50.079454
A18: 4 | B18: 100000 | C18: =B18*$B$10 -> 1000000000 | D18: =CEILING(C18/$B$9,1) -> 34 | E18: =D18*$B$8 -> 169730.28 | F18: =C18*$B$5 -> 10000000 | G18: =F18/E18 -> 58.917005
A19: 5 | B19: 1000000 | C19: =B19*$B$10 -> 10000000000 | D19: =CEILING(C19/$B$9,1) -> 334 | E19: =D19*$B$8 -> 1667350.4 | F19: =C19*$B$5 -> 100000000 | G19: =F19/E19 -> 59.975394

Sheet Fintech
A1: Fintech (Boring Financial) — the density engine
A2: Highest revenue density. Fee is bimodal: model instrument classes separately.
A4: PARAMETERS
A5: Fee r_tx ($/tx) | B5: =Assumptions!$B$29 -> 0.25
A6: Compliance multiplier | B6: =Assumptions!$B$39 -> 2.5
A7: All-in cost C ($/shard-mo) | B7: ='Rent Cost Model'!$D$11 -> 4160.056
A8: Effective cost C_eff ($/shard-mo) | B8: =B6*B7 -> 10400.14
A9: Headroom capacity (tx/shard-mo) | B9: =Assumptions!$B$20 -> 20000000
A10: Break-even traffic (tx/mo) | B10: =B8/B5 -> 41600.56
A11: Break-even load (% of shard) | B11: =B10/B9 -> 0.002080028
A13: Year | B13: Monthly tx | C13: Shards | D13: Cost ($) | E13: Revenue ($) | F13: Margin
A14: 1 | B14: 50000 | C14: =CEILING(B14/$B$9,1) -> 1 | D14: =C14*$B$8 -> 10400.14 | E14: =B14*$B$5 -> 12500 | F14: =E14/D14 -> 1.2019069
A15: 2 | B15: 500000 | C15: =CEILING(B15/$B$9,1) -> 1 | D15: =C15*$B$8 -> 10400.14 | E15: =B15*$B$5 -> 125000 | F15: =E15/D15 -> 12.019069
A16: 3 | B16: 5000000 | C16: =CEILING(B16/$B$9,1) -> 1 | D16: =C16*$B$8 -> 10400.14 | E16: =B16*$B$5 -> 1250000 | F16: =E16/D16 -> 120.19069
A17: 4 | B17: 50000000 | C17: =CEILING(B17/$B$9,1) -> 3 | D17: =C17*$B$8 -> 31200.42 | E17: =B17*$B$5 -> 12500000 | F17: =E17/D17 -> 400.63563
A18: 5 | B18: 500000000 | C18: =CEILING(B18/$B$9,1) -> 25 | D18: =C18*$B$8 -> 260003.5 | E18: =B18*$B$5 -> 125000000 | F18: =E18/D18 -> 480.76276

Sheet Medical
A1: Medical (VA) — the cohort-capped annuity
A2: Logistic growth, hard cohort ceiling, highest assurance. Deploys last.
A4: PARAMETERS
A5: Enrolled cohort (veterans) | B5: 9100000
A6: Target share | B6: 0.8
A7: Target patients | B7: =B5*B6 -> 7280000
A8: $/patient/month (R) | B8: =Assumptions!$B$31 -> 1
A9: tx/patient/month (τ) | B9: =Assumptions!$B$32 -> 50
A10: Compliance multiplier | B10: =Assumptions!$B$40 -> 4
A11: All-in cost C ($/shard-mo) | B11: ='Rent Cost Model'!$D$11 -> 4160.056
A12: Effective cost C_eff ($/shard-mo) | B12: =B11*B10 -> 16640.224
A13: Headroom capacity (tx/shard-mo) | B13: =Assumptions!$B$20 -> 20000000
A14: Break-even patients | B14: =B12/B8 -> 16640.224
A15: Patients per shard | B15: =B13/B9 -> 400000
A16: Break-even load (% of shard) | B16: =B14/B15 -> 0.04160056
A18: Year | B18: Patients | C18: Monthly tx | D18: Shards | E18: Cost ($) | F18: Revenue ($) | G18: Margin | H18: Annual rev ($) | I18: Annual cost ($)
A19: 1 | B19: 7280 | C19: =B19*$B$9 -> 364000 | D19: =CEILING(C19/$B$13,1) -> 1 | E19: =D19*$B$12 -> 16640.224 | F19: =B19*$B$8 -> 7280 | G19: =F19/E19 -> 0.43749411 | H19: =F19*12 -> 87360 | I19: =E19*12 -> 199682.69
A20: 2 | B20: 72800 | C20: =B20*$B$9 -> 3640000 | D20: =CEILING(C20/$B$13,1) -> 1 | E20: =D20*$B$12 -> 16640.224 | F20: =B20*$B$8 -> 72800 | G20: =F20/E20 -> 4.3749411 | H20: =F20*12 -> 873600 | I20: =E20*12 -> 199682.69
A21: 3 | B21: 728000 | C21: =B21*$B$9 -> 36400000 | D21: =CEILING(C21/$B$13,1) -> 2 | E21: =D21*$B$12 -> 33280.448 | F21: =B21*$B$8 -> 728000 | G21: =F21/E21 -> 21.874706 | H21: =F21*12 -> 8736000 | I21: =E21*12 -> 399365.38
A22: 4 | B22: =$B$7 -> 7280000 | C22: =B22*$B$9 -> 364000000 | D22: =CEILING(C22/$B$13,1) -> 19 | E22: =D22*$B$12 -> 316164.26 | F22: =B22*$B$8 -> 7280000 | G22: =F22/E22 -> 23.026006 | H22: =F22*12 -> 87360000 | I22: =E22*12 -> 3793971.1
A23: 5 | B23: =$B$7 -> 7280000 | C23: =B23*$B$9 -> 364000000 | D23: =CEILING(C23/$B$13,1) -> 19 | E23: =D23*$B$12 -> 316164.26 | F23: =B23*$B$8 -> 7280000 | G23: =F23/E23 -> 23.026006 | H23: =F23*12 -> 87360000 | I23: =E23*12 -> 3793971.1
A24: 6 | B24: =$B$7 -> 7280000 | C24: =B24*$B$9 -> 364000000 | D24: =CEILING(C24/$B$13,1) -> 19 | E24: =D24*$B$12 -> 316164.26 | F24: =B24*$B$8 -> 7280000 | G24: =F24/E24 -> 23.026006 | H24: =F24*12 -> 87360000 | I24: =E24*12 -> 3793971.1
A25: 7 | B25: =$B$7 -> 7280000 | C25: =B25*$B$9 -> 364000000 | D25: =CEILING(C25/$B$13,1) -> 19 | E25: =D25*$B$12 -> 316164.26 | F25: =B25*$B$8 -> 7280000 | G25: =F25/E25 -> 23.026006 | H25: =F25*12 -> 87360000 | I25: =E25*12 -> 3793971.1
A26: 8 | B26: =$B$7 -> 7280000 | C26: =B26*$B$9 -> 364000000 | D26: =CEILING(C26/$B$13,1) -> 19 | E26: =D26*$B$12 -> 316164.26 | F26: =B26*$B$8 -> 7280000 | G26: =F26/E26 -> 23.026006 | H26: =F26*12 -> 87360000 | I26: =E26*12 -> 3793971.1
A27: 9 | B27: =$B$7 -> 7280000 | C27: =B27*$B$9 -> 364000000 | D27: =CEILING(C27/$B$13,1) -> 19 | E27: =D27*$B$12 -> 316164.26 | F27: =B27*$B$8 -> 7280000 | G27: =F27/E27 -> 23.026006 | H27: =F27*12 -> 87360000 | I27: =E27*12 -> 3793971.1
A28: 10 | B28: =$B$7 -> 7280000 | C28: =B28*$B$9 -> 364000000 | D28: =CEILING(C28/$B$13,1) -> 19 | E28: =D28*$B$12 -> 316164.26 | F28: =B28*$B$8 -> 7280000 | G28: =F28/E28 -> 23.026006 | H28: =F28*12 -> 87360000 | I28: =E28*12 -> 3793971.1
A29: Decade total | H29: =SUM(H19:H28) -> 621216960 | I29: =SUM(I19:I28) -> 27356528

Sheet Music
A1: Music — the cold-tail fill
A2: Ten-artist indie stable. High margin but roster-fragile; ideal as packing, not anchor.
A4: PARAMETERS
A5: Artists in stable | B5: 10
A6: Followers per artist | B6: 1000000
A7: Plays per audient / month | B7: 10
A8: Total plays / month | B8: =B5*B6*B7 -> 100000000
A9: Fee r_tx ($/play) | B9: =Assumptions!$B$30 -> 0.0003
A10: All-in cost C ($/shard-mo) | B10: ='Rent Cost Model'!$D$11 -> 4160.056
A11: Dense capacity (tx/shard-mo) | B11: =Assumptions!$B$19 -> 30000000
A12: Shards (per-play, on-chain) | B12: =CEILING(B8/B11,1) -> 4
A13: Cost ($/mo) | B13: =B12*B10 -> 16640.224
A14: Break-even fee ($/play) | B14: =B13/B8 -> 0.00016640224
A16: FEE SENSITIVITY (per-play, on-chain)
A17: Fee / play ($) | B17: Revenue ($) | C17: Cost ($) | D17: Margin
A18: 0.0001 | B18: =$B$8*A18 -> 10000 | C18: =$B$13 -> 16640.224 | D18: =B18/C18 -> 0.60095345
A19: 0.000166 | B19: =$B$8*A19 -> 16600 | C19: =$B$13 -> 16640.224 | D19: =B19/C19 -> 0.99758272
A20: 0.0003 | B20: =$B$8*A20 -> 30000 | C20: =$B$13 -> 16640.224 | D20: =B20/C20 -> 1.8028603
A21: 0.001 | B21: =$B$8*A21 -> 100000 | C21: =$B$13 -> 16640.224 | D21: =B21/C21 -> 6.0095345
A23: BATCHED SETTLEMENT ALTERNATIVE
A24: Batch ratio (plays : settlement) | B24: 100
A25: Batched tx / month | B25: =B8/B24 -> 1000000
A26: Batched shards | B26: =CEILING(B25/B11,1) -> 1
A27: Batched cost ($/mo) | B27: =B26*B10 -> 4160.056
A28: Effective take / settlement ($) | B28: 0.03
A29: Batched revenue ($/mo) | B29: =B25*B28 -> 30000
A30: Batched margin | B30: =B29/B27 -> 7.2114414

Sheet Web 2.0
A1: Web 2.0 — participatory advertising
A2: Users pay network cost in tokenised impressions; one impression covers ~20 payloads.
A4: PARAMETERS
A5: Per-payload cost ($) | B5: ='Rent Cost Model'!$D$13 -> 0.00013866853
A6: Display CPM ($) | B6: =Assumptions!$B$24 -> 3
A7: Per-impression value ($) | B7: =Assumptions!$B$25 -> 0.003
A8: Payloads covered per impression | B8: =B7/B5 -> 21.634324
A9: Dense capacity (tx/shard-mo) | B9: =Assumptions!$B$19 -> 30000000
A10: All-in cost C ($/shard-mo) | B10: ='Rent Cost Model'!$D$11 -> 4160.056
A12: Property | B12: Users | C12: Payloads/mo | D12: Shards | E12: Infra cost ($/mo) | F12: Payloads/user-mo | G12: Cost/user-mo ($) | H12: Break-even ads/user/day
A13: Gmail | B13: 1800000000 | C13: 3600000000000 | D13: =CEILING(C13/$B$9,1) -> 120000 | E13: =D13*$B$10 -> 499206720 | F13: =C13/B13 -> 2000 | G13: =F13*$B$5 -> 0.27733707 | H13: =(G13/$B$7)/30 -> 3.081523
A14: Maps | B14: 2000000000 | C14: 3000000000000 | D14: =CEILING(C14/$B$9,1) -> 100000 | E14: =D14*$B$10 -> 416005600 | F14: =C14/B14 -> 1500 | G14: =F14*$B$5 -> 0.2080028 | H14: =(G14/$B$7)/30 -> 2.3111422
A15: Docs | B15: 3000000000 | C15: 600000000000 | D15: =CEILING(C15/$B$9,1) -> 20000 | E15: =D15*$B$10 -> 83201120 | F15: =C15/B15 -> 200 | G15: =F15*$B$5 -> 0.027733707 | H15: =(G15/$B$7)/30 -> 0.3081523
A17: PRIVACY WEDGE & THIN-MARGIN ECONOMICS
A18: Gmail privacy slice (%) | B18: 0.01
A19: Wedge users | B19: =B13*B18 -> 18000000
A20: Wedge payloads/mo | B20: =C13*B18 -> 36000000000
A21: Wedge shards | B21: =CEILING(B20/B9,1) -> 1200
A22: Wedge infra ($/mo) | B22: =B21*B10 -> 4992067.2
A23: Per-payload take ($) | B23: 2e-05
A24: Gmail-scale monthly take ($) | B24: =C13*B23 -> 72000000

Sheet CAC
A1: Customer Acquisition — Wholesale (anchor) vs Retail (D2C)
A2: Court anchors, not heads. CAC/head = A / (population x conversion).
A4: BENCHMARKS & LEVERS
A5: Facebook D2C CAC ($/head) | B5: 50
A6: WhatsApp D2C CAC ($/head) | B6: 19
A7: Cross-market multiplier m | B7: 4
A9: Channel / anchor | B9: A ($) | C9: Population/anchor | D9: Conversion c | E9: Heads acquired | F9: CAC/head ($) | G9: x vs WhatsApp | H9: x vs Facebook
A10: Music — inbound | B10: 2000 | C10: 1000000 | D10: 0.1 | E10: =C10*D10 -> 100000 | F10: =B10/E10 -> 0.02 | G10: =$B$6/F10 -> 950 | H10: =$B$5/F10 -> 2500
A11: Music — mid | B11: 5000 | C11: 1000000 | D11: 0.05 | E11: =C11*D11 -> 50000 | F11: =B11/E11 -> 0.1 | G11: =$B$6/F11 -> 190 | H11: =$B$5/F11 -> 500
A12: Music — conservative | B12: 10000 | C12: 1000000 | D12: 0.01 | E12: =C12*D12 -> 10000 | F12: =B12/E12 -> 1 | G12: =$B$6/F12 -> 19 | H12: =$B$5/F12 -> 50
A13: Healthcare — mid hospital | B13: 500000 | C13: 1000000 | D13: 1 | E13: =C13*D13 -> 1000000 | F13: =B13/E13 -> 0.5 | G13: =$B$6/F13 -> 38 | H13: =$B$5/F13 -> 100
A14: VA — conservative | B14: 5000000 | C14: 9100000 | D14: 0.8 | E14: =C14*D14 -> 7280000 | F14: =B14/E14 -> 0.68681319 | G14: =$B$6/F14 -> 27.664 | H14: =$B$5/F14 -> 72.8
A15: VA — heavy gov. sale | B15: 20000000 | C15: 9100000 | D15: 0.8 | E15: =C15*D15 -> 7280000 | F15: =B15/E15 -> 2.7472527 | G15: =$B$6/F15 -> 6.916 | H15: =$B$5/F15 -> 18.2
A17: LTV & PAYBACK
A18: Channel | B18: CAC/head ($) | C18: LTV ($/head-mo) | D18: Payback (mo, 1 market) | E18: Eff. CAC w/ cross-mkt ($) | F18: Payback (mo, cross-mkt)
A19: Music (conservative) | B19: =F12 -> 1 | C19: =Music!$B$7*Music!$B$9 -> 0.003 | D19: =B19/C19 -> 333.33333 | E19: =B19/$B$7 -> 0.25 | F19: =B19/(C19*$B$7) -> 83.333333
A20: Healthcare (VA conservative) | B20: =F14 -> 0.68681319 | C20: =Assumptions!$B$31 -> 1 | D20: =B20/C20 -> 0.68681319 | E20: =B20/$B$7 -> 0.1717033 | F20: =B20/(C20*$B$7) -> 0.1717033
A22: Note: music's true cross-market LTV is dominated by direct artist sales (a $10 album at a 3% fee = $0.30), not 4x streaming; m is a coarse lever.

Sheet Connector
A1: Connector Shard — Cross-Shard Interchange
A2: Where F1R3FLY taxes value moving between shards. Revenue ~ volume x chi x fee.
A4: PARAMETERS
A5: Core cross-shard fee r_x ($/tx) | B5: 0.005
A6: Core effective χ | B6: 0.2
A7: Web 2.0 cross-shard fee ($/payload) | B7: 0.0005
A8: Web 2.0 effective χ | B8: 0.05
A9: Dense capacity (tx/shard-mo) | B9: =Assumptions!$B$19 -> 30000000
A10: All-in cost C ($/shard-mo) | B10: ='Rent Cost Model'!$D$11 -> 4160.056
A12: CONNECTABLE VOLUME (mature, linked from sector tabs)
A13: AI (year 5) | B13: =AI!$C$19 -> 10000000000
A14: Fintech (year 5) | B14: =Fintech!$B$18 -> 500000000
A15: Medical (plateau) | B15: =Medical!$C$28 -> 364000000
A16: Music (plays) | B16: =Music!$B$8 -> 100000000
A17: Core total (tx/mo) | B17: =SUM(B13:B16) -> 10964000000
A18: Web 2.0 payloads (if connected) | B18: ='Web 2.0'!$C$13+'Web 2.0'!$C$14+'Web 2.0'!$C$15 -> 7200000000000
A20: CONNECTOR ECONOMICS
A21: Core cross-shard tx / mo | B21: =B17*B6 -> 2192800000
A22: Core connector revenue / mo | B22: =B21*B5 -> 10964000
A23: Web 2.0 cross-shard tx / mo | B23: =B18*B8 -> 360000000000
A24: Web 2.0 connector revenue / mo | B24: =B23*B7 -> 180000000
A25: Total connector revenue / mo | B25: =B22+B24 -> 190964000
A26: Connector infra shards | B26: =CEILING((B21+B23)/B9,1) -> 12074
A27: Connector cost / mo | B27: =B26*B10 -> 50228516
A28: Connector margin | B28: =B25/B27 -> 3.8019041
A30: METCALFE: χ -> (n-1)/n grows the core tax base
A31: Connected shards n | B31: χ = (n-1)/n | C31: Core connector rev/mo
A32: 2 | B32: =(A32-1)/A32 -> 0.5 | C32: =$B$17*B32*$B$5 -> 27410000
A33: 5 | B33: =(A33-1)/A33 -> 0.8 | C33: =$B$17*B33*$B$5 -> 43856000
A34: 10 | B34: =(A34-1)/A34 -> 0.9 | C34: =$B$17*B34*$B$5 -> 49338000
A35: 50 | B35: =(A35-1)/A35 -> 0.98 | C35: =$B$17*B35*$B$5 -> 53723600
A36: 100 | B36: =(A36-1)/A36 -> 0.99 | C36: =$B$17*B36*$B$5 -> 54271800

Sheet Bandwidth
A1: Bandwidth — Media Egress (the per-byte exception)
A2: Egress = payload size x moves x rate. Negligible for text; dominant for imaging/lossless audio.
A4: PARAMETERS (linked from Assumptions)
A5: Internet egress ($/GB) | B5: =Assumptions!$B$43 -> 0.0085
A6: CDN / edge egress ($/GB) | B6: =Assumptions!$B$45 -> 0.04
A7: Inter-region egress ($/GB) | B7: =Assumptions!$B$44 -> 0.005
A8: Free egress tier (TB/mo) | B8: =Assumptions!$B$46 -> 10
A9: Note: first 10TB/mo free (per tenancy); Oracle reportedly moved to free egress across all regions Feb 2026. Figures below are marginal egress at scale (free tier negligible).
A11: EGRESS BY SCENARIO
A12: Scenario | B12: Payload (MB) | C12: Payloads/mo | D12: GB moved/mo | E12: Egress @ internet ($/mo) | F12: Egress @ CDN ($/mo) | G12: Egress/payload ($) | H12: % of sector rev
A13: Radiology (medical imaging) | B13: =Assumptions!$B$49 -> 250 | C13: =Medical!$B$7*Assumptions!$B$52 -> 36400000 | D13: =C13*B13/1024 -> 8886718.8 | E13: =D13*$B$5 -> 75537.109 | F13: =D13*$B$6 -> 355468.75 | G13: =E13/C13 -> 0.0020751953 | H13: =E13/Medical!$F$28 -> 0.010375977
A14: Music, compressed | B14: =Assumptions!$B$50 -> 4 | C14: =Music!$B$8 -> 100000000 | D14: =C14*B14/1024 -> 390625 | E14: =D14*$B$5 -> 3320.3125 | F14: =D14*$B$6 -> 15625 | G14: =E14/C14 -> 3.3203125e-05 | H14: =E14/Music!$B$20 -> 0.11067708
A15: Music, lossless / hi-res | B15: =Assumptions!$B$51 -> 40 | C15: =Music!$B$8 -> 100000000 | D15: =C15*B15/1024 -> 3906250 | E15: =D15*$B$5 -> 33203.125 | F15: =D15*$B$6 -> 156250 | G15: =E15/C15 -> 0.00033203125 | H15: =E15/Music!$B$20 -> 1.1067708
A16: Transactional (AI / fintech / EHR record) | B16: 0.003 | C16: =AI!$C$19 -> 10000000000 | D16: =C16*B16/1024 -> 29296.875 | E16: =D16*$B$5 -> 249.02344 | F16: =D16*$B$6 -> 1171.875 | G16: =E16/C16 -> 2.4902344e-08 | H16: negligible
A18: MUSIC: BANDWIDTH-INCLUSIVE BREAK-EVEN FEE
A19: Music shard+compute cost ($/mo) | B19: =Music!$B$13 -> 16640.224
A20: Break-even fee, compressed ($/play) | B20: =(B19+E14)/C14 -> 0.00019960537
A21: Break-even fee, lossless ($/play) | B21: =(B19+E15)/C15 -> 0.00049843349
A22: Current streaming fee ($/play) | B22: =Assumptions!$B$30 -> 0.0003
A23: Note: lossless exceeds the streaming fee -- needs a higher fee or edge caching.

Sheet Summary
A1: Summary — Five Sectors plus Web 2.0
A2: Break-even loads link live to each sector tab.
A4: Sector | B4: Revenue density | C4: Risk | D4: Boundedness | E4: Break-even load | F4: Strategic role
A5: AI | B5: $0.01 / tx | C5: low–mod | D5: none (machine vol.) | E5: =AI!$B$12 -> 0.016640224 | F5: anchor / growth
A6: Fintech | B6: ~$0.25 / tx | C6: high | D6: semi-bounded | E6: =Fintech!$B$11 -> 0.002080028 | F6: margin engine
A7: Medical | B7: high / patient | C7: highest | D7: hard cohort cap | E7: =Medical!$B$16 -> 0.04160056 | F7: cash-cow annuity
A8: Music | B8: $0.0003 / tx | C8: low | D8: roster-dependent | E8: ~near full | F8: cold-tail fill
A9: Web 2.0 | B9: ad-funded | C9: low–mod | D9: astronomical | E9: ~3 ads/day | F9: mass-market moat
A12: Rollout order: | B12: AI (anchor) → Fintech (margin) → Medical (annuity); Music = continuous fill; Web 2.0 = mass-market substrate via privacy wedge.
A14: Cross-cutting: | B14: CAC tab = wholesale (anchor) acquisition economics. Connector tab = the cross-shard interchange where the network monetises interoperability — the apex revenue layer at scale.

Sheet Mgmt Assumptions
A1: Shard-Tree Management — Assumptions & Levers
A2: Inputs for the agent-vs-DevOps crossover. Blue = lever; green = cross-sheet link. Sources noted at right.
A4: LABOR (loaded human cost)
A5: SRE / DevOps total comp ($/yr) | B5: 150000 | C5: $/yr | D5: Source: Built In 2026 avg total comp SRE $147k / DevOps $150k
A6: Loading factor (benefits, overhead, mgmt, equip) | B6: 1.6 | C6: x | D6: fully-loaded employer cost / comp
A7: Loaded SRE cost ($/mo) | B7: =B5*B6/12 -> 20000 | C7: $/mo
A8: DevOps span of control sigma_h (shards/SRE) | B8: 30 | C8: shards/SRE | D8: stateful 10-node consensus clusters w/ IaC
A9: DevOps coverage floor (min SREs, 24/7 rotation) | B9: 2 | C9: SREs | D9: 2 = lean pager rotation; 4-5 = true 24/7 SLA
A10: Hybrid span of control sigma_hy (shards/SRE) | B10: 300 | C10: shards/SRE | D10: agent absorbs routine; human handles exceptions -> ~10x reach
A11: Hybrid exception floor (min SREs) | B11: 1 | C11: SREs | D11: one human reachable for hardware / SLA escalation
A13: AGENT PLATFORM (fixed cost of having an ops-agent)
A14: Platform-owner FTEs (harness, evals, guardrails) | B14: 1.25 | C14: FTE | D14: engineers who build/maintain the agent, not per-shard
A15: Agent tooling / observability ($/mo) | B15: 3000 | C15: $/mo | D15: telemetry pipeline, eval harness, run logging
A16: Agent platform fixed cost ($/mo) | B16: =B14*B7+B15 -> 28000 | C16: $/mo
A17: Full-auto premium-support / SLA retainer ($/mo) | B17: 2000 | C17: $/mo | D17: cloud-native: provider swaps disks; premium support for SLA disputes
A19: MODEL PRICES ($/MTok, Anthropic API, Jun 2026)
A20: Model | B20: Input | C20: Output | D20: note
A21: Haiku 4.5 | B21: 1 | C21: 5 | D21: routine monitoring
A22: Sonnet 4.6 | B22: 3 | C22: 15 | D22: provisioning / config
A23: Opus 4.8 | B23: 5 | C23: 25 | D23: hard decisions: split / migrate / triage
A24: Cache multiplier (cached input price / fresh) | B24: 0.1 | C24: x | D24: prompt caching = 90% off cached input
A26: AGENT WORKLOAD (per shard)
A27: Activity | B27: rate | C27: in tok | D27: out tok
A28: Routine checks / shard / DAY | B28: 24 | C28: 4000 | D28: 500
A29: routine cached-input fraction | B29: 0.8
A30: Hard decisions / shard / MONTH | B30: 6 | C30: 30000 | D30: 6000
A31: hard cached-input fraction | B31: 0.5
A32: Provisioning episodes / shard / MONTH | B32: 0.5 | C32: 50000 | D32: 12000
A33: provisioning cached-input fraction | B33: 0

Sheet Agent Cost
A1: Agent Inference Cost — per Shard-Month
A2: Transparent token build-up of what it costs an agent to manage ONE shard for one month. Green = linked to Mgmt Assumptions.
A4: Activity | B4: calls / shard-mo | C4: in tok | D4: cached frac | E4: out tok | F4: $ input / call | G4: $ output / call | H4: $ / shard-mo
A5: Routine monitoring (Haiku 4.5) | B5: ='Mgmt Assumptions'!$B$28*30 -> 720 | C5: ='Mgmt Assumptions'!$C$28 -> 4000 | D5: ='Mgmt Assumptions'!$B$29 -> 0.8 | E5: ='Mgmt Assumptions'!$D$28 -> 500 | F5: =(D5*C5*'Mgmt Assumptions'!$B$21*'Mgmt Assumptions'!$B$24+(1-D5)*C5*'Mgmt Assumptions'!$B$21)/1000000 -> 0.00112 | G5: =E5*'Mgmt Assumptions'!$C$21/1000000 -> 0.0025 | H5: =B5*(F5+G5) -> 2.6064
A6: Hard decisions (Opus 4.8) | B6: ='Mgmt Assumptions'!$B$30 -> 6 | C6: ='Mgmt Assumptions'!$C$30 -> 30000 | D6: ='Mgmt Assumptions'!$B$31 -> 0.5 | E6: ='Mgmt Assumptions'!$D$30 -> 6000 | F6: =(D6*C6*'Mgmt Assumptions'!$B$23*'Mgmt Assumptions'!$B$24+(1-D6)*C6*'Mgmt Assumptions'!$B$23)/1000000 -> 0.0825 | G6: =E6*'Mgmt Assumptions'!$C$23/1000000 -> 0.15 | H6: =B6*(F6+G6) -> 1.395
A7: Provisioning / stand-up (Sonnet 4.6) | B7: ='Mgmt Assumptions'!$B$32 -> 0.5 | C7: ='Mgmt Assumptions'!$C$32 -> 50000 | D7: ='Mgmt Assumptions'!$B$33 -> 0 | E7: ='Mgmt Assumptions'!$D$32 -> 12000 | F7: =(D7*C7*'Mgmt Assumptions'!$B$22*'Mgmt Assumptions'!$B$24+(1-D7)*C7*'Mgmt Assumptions'!$B$22)/1000000 -> 0.15 | G7: =E7*'Mgmt Assumptions'!$C$22/1000000 -> 0.18 | H7: =B7*(F7+G7) -> 0.165
A8: TOTAL agent inference a ($/shard-mo) | H8: =SUM(H5:H7) -> 4.1664
A10: For comparison:
A11: Infra cost per shard C ($/shard-mo) | H11: ='Rent Cost Model'!$D$11 -> 4160.056
A12: Agent mgmt as % of infra | H12: =H8/H11 -> 0.001001525
A13: Human marginal cost / shard, pure DevOps ($/shard-mo) | H13: ='Mgmt Assumptions'!$B$7/'Mgmt Assumptions'!$B$8 -> 666.66667
A14: Human marginal cost / shard, hybrid ($/shard-mo) | H14: ='Mgmt Assumptions'!$B$7/'Mgmt Assumptions'!$B$10 -> 66.666667

Sheet Mgmt Crossover
A1: Management Crossover — Agent vs DevOps vs Hybrid
A2: Monthly management cost of the WHOLE shard tree as it grows. Three regimes. Cheapest is highlighted; the flip is the crossover.
A3: Anchors: | B3: agent a ($/shard-mo) | C3: ='Agent Cost'!$H$8 -> 4.1664 | D3: infra C ($/shard-mo) | E3: ='Rent Cost Model'!$D$11 -> 4160.056
A5: Shards S | B5: DevOps SREs | C5: DevOps $/mo | D5: Full-Auto $/mo (floor) | E5: Hybrid SREs | F5: Hybrid $/mo | G5: Feasible best | H5: DevOps $/shard | I5: Hybrid $/shard | J5: Infra $/mo | K5: Hybrid mgmt % of infra | L5: DevOps mgmt % of infra
A6: 1 | B6: =MAX('Mgmt Assumptions'!$B$9,CEILING(A6/'Mgmt Assumptions'!$B$8,1)) -> 2 | C6: =B6*'Mgmt Assumptions'!$B$7 -> 40000 | D6: ='Mgmt Assumptions'!$B$16+'Mgmt Assumptions'!$B$17+A6*$C$3 -> 30004.166 | E6: =MAX('Mgmt Assumptions'!$B$11,CEILING(A6/'Mgmt Assumptions'!$B$10,1)) -> 1 | F6: ='Mgmt Assumptions'!$B$16+A6*$C$3+E6*'Mgmt Assumptions'!$B$7 -> 48004.166 | G6: =IF(F6<C6,"Hybrid","DevOps") -> DevOps | H6: =C6/A6 -> 40000 | I6: =F6/A6 -> 48004.166 | J6: =A6*$E$3 -> 4160.056 | K6: =F6/J6 -> 11.539308 | L6: =C6/J6 -> 9.6152552
A7: 2 | B7: =MAX('Mgmt Assumptions'!$B$9,CEILING(A7/'Mgmt Assumptions'!$B$8,1)) -> 2 | C7: =B7*'Mgmt Assumptions'!$B$7 -> 40000 | D7: ='Mgmt Assumptions'!$B$16+'Mgmt Assumptions'!$B$17+A7*$C$3 -> 30008.333 | E7: =MAX('Mgmt Assumptions'!$B$11,CEILING(A7/'Mgmt Assumptions'!$B$10,1)) -> 1 | F7: ='Mgmt Assumptions'!$B$16+A7*$C$3+E7*'Mgmt Assumptions'!$B$7 -> 48008.333 | G7: =IF(F7<C7,"Hybrid","DevOps") -> DevOps | H7: =C7/A7 -> 20000 | I7: =F7/A7 -> 24004.166 | J7: =A7*$E$3 -> 8320.112 | K7: =F7/J7 -> 5.7701546 | L7: =C7/J7 -> 4.8076276
A8: 5 | B8: =MAX('Mgmt Assumptions'!$B$9,CEILING(A8/'Mgmt Assumptions'!$B$8,1)) -> 2 | C8: =B8*'Mgmt Assumptions'!$B$7 -> 40000 | D8: ='Mgmt Assumptions'!$B$16+'Mgmt Assumptions'!$B$17+A8*$C$3 -> 30020.832 | E8: =MAX('Mgmt Assumptions'!$B$11,CEILING(A8/'Mgmt Assumptions'!$B$10,1)) -> 1 | F8: ='Mgmt Assumptions'!$B$16+A8*$C$3+E8*'Mgmt Assumptions'!$B$7 -> 48020.832 | G8: =IF(F8<C8,"Hybrid","DevOps") -> DevOps | H8: =C8/A8 -> 8000 | I8: =F8/A8 -> 9604.1664 | J8: =A8*$E$3 -> 20800.28 | K8: =F8/J8 -> 2.3086628 | L8: =C8/J8 -> 1.923051
A9: 10 | B9: =MAX('Mgmt Assumptions'!$B$9,CEILING(A9/'Mgmt Assumptions'!$B$8,1)) -> 2 | C9: =B9*'Mgmt Assumptions'!$B$7 -> 40000 | D9: ='Mgmt Assumptions'!$B$16+'Mgmt Assumptions'!$B$17+A9*$C$3 -> 30041.664 | E9: =MAX('Mgmt Assumptions'!$B$11,CEILING(A9/'Mgmt Assumptions'!$B$10,1)) -> 1 | F9: ='Mgmt Assumptions'!$B$16+A9*$C$3+E9*'Mgmt Assumptions'!$B$7 -> 48041.664 | G9: =IF(F9<C9,"Hybrid","DevOps") -> DevOps | H9: =C9/A9 -> 4000 | I9: =F9/A9 -> 4804.1664 | J9: =A9*$E$3 -> 41600.56 | K9: =F9/J9 -> 1.1548321 | L9: =C9/J9 -> 0.96152552
A10: 25 | B10: =MAX('Mgmt Assumptions'!$B$9,CEILING(A10/'Mgmt Assumptions'!$B$8,1)) -> 2 | C10: =B10*'Mgmt Assumptions'!$B$7 -> 40000 | D10: ='Mgmt Assumptions'!$B$16+'Mgmt Assumptions'!$B$17+A10*$C$3 -> 30104.16 | E10: =MAX('Mgmt Assumptions'!$B$11,CEILING(A10/'Mgmt Assumptions'!$B$10,1)) -> 1 | F10: ='Mgmt Assumptions'!$B$16+A10*$C$3+E10*'Mgmt Assumptions'!$B$7 -> 48104.16 | G10: =IF(F10<C10,"Hybrid","DevOps") -> DevOps | H10: =C10/A10 -> 1600 | I10: =F10/A10 -> 1924.1664 | J10: =A10*$E$3 -> 104001.4 | K10: =F10/J10 -> 0.46253377 | L10: =C10/J10 -> 0.38461021
A11: 50 | B11: =MAX('Mgmt Assumptions'!$B$9,CEILING(A11/'Mgmt Assumptions'!$B$8,1)) -> 2 | C11: =B11*'Mgmt Assumptions'!$B$7 -> 40000 | D11: ='Mgmt Assumptions'!$B$16+'Mgmt Assumptions'!$B$17+A11*$C$3 -> 30208.32 | E11: =MAX('Mgmt Assumptions'!$B$11,CEILING(A11/'Mgmt Assumptions'!$B$10,1)) -> 1 | F11: ='Mgmt Assumptions'!$B$16+A11*$C$3+E11*'Mgmt Assumptions'!$B$7 -> 48208.32 | G11: =IF(F11<C11,"Hybrid","DevOps") -> DevOps | H11: =C11/A11 -> 800 | I11: =F11/A11 -> 964.1664 | J11: =A11*$E$3 -> 208002.8 | K11: =F11/J11 -> 0.23176765 | L11: =C11/J11 -> 0.1923051
A12: 60 | B12: =MAX('Mgmt Assumptions'!$B$9,CEILING(A12/'Mgmt Assumptions'!$B$8,1)) -> 2 | C12: =B12*'Mgmt Assumptions'!$B$7 -> 40000 | D12: ='Mgmt Assumptions'!$B$16+'Mgmt Assumptions'!$B$17+A12*$C$3 -> 30249.984 | E12: =MAX('Mgmt Assumptions'!$B$11,CEILING(A12/'Mgmt Assumptions'!$B$10,1)) -> 1 | F12: ='Mgmt Assumptions'!$B$16+A12*$C$3+E12*'Mgmt Assumptions'!$B$7 -> 48249.984 | G12: =IF(F12<C12,"Hybrid","DevOps") -> DevOps | H12: =C12/A12 -> 666.66667 | I12: =F12/A12 -> 804.1664 | J12: =A12*$E$3 -> 249603.36 | K12: =F12/J12 -> 0.19330663 | L12: =C12/J12 -> 0.16025425
A13: 90 | B13: =MAX('Mgmt Assumptions'!$B$9,CEILING(A13/'Mgmt Assumptions'!$B$8,1)) -> 3 | C13: =B13*'Mgmt Assumptions'!$B$7 -> 60000 | D13: ='Mgmt Assumptions'!$B$16+'Mgmt Assumptions'!$B$17+A13*$C$3 -> 30374.976 | E13: =MAX('Mgmt Assumptions'!$B$11,CEILING(A13/'Mgmt Assumptions'!$B$10,1)) -> 1 | F13: ='Mgmt Assumptions'!$B$16+A13*$C$3+E13*'Mgmt Assumptions'!$B$7 -> 48374.976 | G13: =IF(F13<C13,"Hybrid","DevOps") -> Hybrid | H13: =C13/A13 -> 666.66667 | I13: =F13/A13 -> 537.49973 | J13: =A13*$E$3 -> 374405.04 | K13: =F13/J13 -> 0.12920493 | L13: =C13/J13 -> 0.16025425
A14: 100 | B14: =MAX('Mgmt Assumptions'!$B$9,CEILING(A14/'Mgmt Assumptions'!$B$8,1)) -> 4 | C14: =B14*'Mgmt Assumptions'!$B$7 -> 80000 | D14: ='Mgmt Assumptions'!$B$16+'Mgmt Assumptions'!$B$17+A14*$C$3 -> 30416.64 | E14: =MAX('Mgmt Assumptions'!$B$11,CEILING(A14/'Mgmt Assumptions'!$B$10,1)) -> 1 | F14: ='Mgmt Assumptions'!$B$16+A14*$C$3+E14*'Mgmt Assumptions'!$B$7 -> 48416.64 | G14: =IF(F14<C14,"Hybrid","DevOps") -> Hybrid | H14: =C14/A14 -> 800 | I14: =F14/A14 -> 484.1664 | J14: =A14*$E$3 -> 416005.6 | K14: =F14/J14 -> 0.11638459 | L14: =C14/J14 -> 0.1923051
A15: 250 | B15: =MAX('Mgmt Assumptions'!$B$9,CEILING(A15/'Mgmt Assumptions'!$B$8,1)) -> 9 | C15: =B15*'Mgmt Assumptions'!$B$7 -> 180000 | D15: ='Mgmt Assumptions'!$B$16+'Mgmt Assumptions'!$B$17+A15*$C$3 -> 31041.6 | E15: =MAX('Mgmt Assumptions'!$B$11,CEILING(A15/'Mgmt Assumptions'!$B$10,1)) -> 1 | F15: ='Mgmt Assumptions'!$B$16+A15*$C$3+E15*'Mgmt Assumptions'!$B$7 -> 49041.6 | G15: =IF(F15<C15,"Hybrid","DevOps") -> Hybrid | H15: =C15/A15 -> 720 | I15: =F15/A15 -> 196.1664 | J15: =A15*$E$3 -> 1040014 | K15: =F15/J15 -> 0.04715475 | L15: =C15/J15 -> 0.17307459
A16: 334 | B16: =MAX('Mgmt Assumptions'!$B$9,CEILING(A16/'Mgmt Assumptions'!$B$8,1)) -> 12 | C16: =B16*'Mgmt Assumptions'!$B$7 -> 240000 | D16: ='Mgmt Assumptions'!$B$16+'Mgmt Assumptions'!$B$17+A16*$C$3 -> 31391.578 | E16: =MAX('Mgmt Assumptions'!$B$11,CEILING(A16/'Mgmt Assumptions'!$B$10,1)) -> 2 | F16: ='Mgmt Assumptions'!$B$16+A16*$C$3+E16*'Mgmt Assumptions'!$B$7 -> 69391.578 | G16: =IF(F16<C16,"Hybrid","DevOps") -> Hybrid | H16: =C16/A16 -> 718.56287 | I16: =F16/A16 -> 207.75921 | J16: =A16*$E$3 -> 1389458.7 | K16: =F16/J16 -> 0.049941447 | L16: =C16/J16 -> 0.17272913
A17: 500 | B17: =MAX('Mgmt Assumptions'!$B$9,CEILING(A17/'Mgmt Assumptions'!$B$8,1)) -> 17 | C17: =B17*'Mgmt Assumptions'!$B$7 -> 340000 | D17: ='Mgmt Assumptions'!$B$16+'Mgmt Assumptions'!$B$17+A17*$C$3 -> 32083.2 | E17: =MAX('Mgmt Assumptions'!$B$11,CEILING(A17/'Mgmt Assumptions'!$B$10,1)) -> 2 | F17: ='Mgmt Assumptions'!$B$16+A17*$C$3+E17*'Mgmt Assumptions'!$B$7 -> 70083.2 | G17: =IF(F17<C17,"Hybrid","DevOps") -> Hybrid | H17: =C17/A17 -> 680 | I17: =F17/A17 -> 140.1664 | J17: =A17*$E$3 -> 2080028 | K17: =F17/J17 -> 0.033693393 | L17: =C17/J17 -> 0.16345934
... A22: 12074 | B22: =MAX('Mgmt Assumptions'!$B$9,CEILING(A22/'Mgmt Assumptions'!$B$8,1)) -> 403 | C22: =B22*'Mgmt Assumptions'!$B$7 -> 8060000 | D22: ='Mgmt Assumptions'!$B$16+'Mgmt Assumptions'!$B$17+A22*$C$3 -> 80305.114 | E22: =MAX('Mgmt Assumptions'!$B$11,CEILING(A22/'Mgmt Assumptions'!$B$10,1)) -> 41 | F22: ='Mgmt Assumptions'!$B$16+A22*$C$3+E22*'Mgmt Assumptions'!$B$7 -> 898305.11 | G22: =IF(F22<C22,"Hybrid","DevOps") -> Hybrid | H22: =C22/A22 -> 667.55011 | I22: =F22/A22 -> 74.39996 | J22: =A22*$E$3 -> 50228516 | K22: =F22/J22 -> 0.017884365 | L22: =C22/J22 -> 0.16046662
A24: CROSSOVER & VERDICT
A25: Hybrid beats DevOps above ~ (shards) | C25: =INDEX(A6:A22,MATCH(TRUE(),INDEX(F6:F22<C6:C22,0),0)) -> 90
A26: Full-Auto beats DevOps above ~ (shards) | C26: =INDEX(A6:A22,MATCH(TRUE(),INDEX(D6:D22<C6:C22,0),0)) -> 1
A27: At connector maturity (12,074 shards): DevOps vs Hybrid saving | C27: =C22-F22 -> 7161694.9
A28: ... Hybrid as a fraction of DevOps cost there | C28: =F22/C22 -> 0.11145225
A29: Reading the table:
A30: - DevOps cost is a STEP function: a high 24/7 coverage floor, then steep marginal cost (one SRE per sigma_h shards).
A31: - Full-Auto is nearly FLAT: a fixed agent-platform cost plus ~$ a few /shard of inference. In raw dollars it is cheapest at
A32: EVERY scale -- but it is a price FLOOR, not a deployable plan: agents cannot swap a failed disk or litigate an SLA.
A33: - The feasible choice is therefore DevOps vs HYBRID (col G). Hybrid = Full-Auto inference + a thin human team sized by
A34: EXCEPTION rate (sigma_hy >> sigma_h), not by shard count. Below the crossover, a lean human team is cheaper than
A35: standing up + owning the agent platform; above it, human marginal cost ($/sigma_h per shard) dominates and Hybrid wins.
A36: - All values are driven by 'Mgmt Assumptions'. Raise the DevOps floor toward 4-5 (strict 24/7 SLA) and Hybrid wins from S=1.

Sheet Local Inference
A1: Local Inference — Self-Hosted Model vs Third-Party API
A2: Dedicate GPU hardware to the agent's model and inference becomes a FIXED step cost (cheap only when busy), not per-token opex.
A4: DEDICATED GPU (OCI inference shape, e.g. L40S 48GB / A10)
A5: GPU shape list price ($/GPU-hr, PAYG) | B5: 1.5 | C5: $/hr | D5: Source: OCI A10/L40S ~$1.20-2.00 PAYG; 3-yr Universal Credits ~$0.85
A6: Hours per month | B6: =Assumptions!$B$10 -> 730 | C6: h
A7: GPU node cost ($/mo) | B7: =B5*B6 -> 1095 | C7: $/mo
A8: Sustained throughput (tokens/sec/GPU) | B8: 5000 | C8: tok/s | D8: small/mid open model, quantized, continuous batching
A9: Max sustainable utilization | B9: 0.7 | D9: headroom for bursts; cannot run a shared service at 100%
A10: Effective capacity (tokens/GPU/mo) | B10: =B8*3600*B6*B9 -> 9198000000 | C10: tok/mo
A12: ROUTINE WORKLOAD (the self-hostable tier)
A13: Routine tokens / shard-mo | B13: ='Agent Cost'!$B$5*('Agent Cost'!$C$5+'Agent Cost'!$E$5) -> 3240000 | C13: tok | D13: 720 calls x (4000 in + 500 out)
A14: Routine API cost / shard-mo (Haiku 4.5) | B14: ='Agent Cost'!$H$5 -> 2.6064 | C14: $/shard
A15: Shards one GPU saturates | B15: =B10/B13 -> 2838.8889 | C15: shards/GPU
A16: Break-even tree size (1 GPU < API) | B16: =B7/B14 -> 420.11971 | C16: shards | D16: below this, the GPU sits idle and API is cheaper
A18: Shards S | B18: Routine tokens/mo | C18: GPUs needed | D18: GPU util | E18: Local routine $/mo | F18: Local $/shard | G18: API routine $/mo | H18: API $/shard | I18: Cheaper | J18: Local % of API
A19: 1 | B19: =A19*$B$13 -> 3240000 | C19: =CEILING(B19/$B$10,1) -> 1 | D19: =B19/(C19*$B$10) -> 0.00035225049 | E19: =C19*$B$7 -> 1095 | F19: =E19/A19 -> 1095 | G19: =A19*$B$14 -> 2.6064 | H19: =$B$14 -> 2.6064 | I19: =IF(E19<G19,"Local","API") -> API | J19: =E19/G19 -> 420.11971
A20: 2 | B20: =A20*$B$13 -> 6480000 | C20: =CEILING(B20/$B$10,1) -> 1 | D20: =B20/(C20*$B$10) -> 0.00070450098 | E20: =C20*$B$7 -> 1095 | F20: =E20/A20 -> 547.5 | G20: =A20*$B$14 -> 5.2128 | H20: =$B$14 -> 2.6064 | I20: =IF(E20<G20,"Local","API") -> API | J20: =E20/G20 -> 210.05985
A21: 5 | B21: =A21*$B$13 -> 16200000 | C21: =CEILING(B21/$B$10,1) -> 1 | D21: =B21/(C21*$B$10) -> 0.0017612524 | E21: =C21*$B$7 -> 1095 | F21: =E21/A21 -> 219 | G21: =A21*$B$14 -> 13.032 | H21: =$B$14 -> 2.6064 | I21: =IF(E21<G21,"Local","API") -> API | J21: =E21/G21 -> 84.023941
A22: 10 | B22: =A22*$B$13 -> 32400000 | C22: =CEILING(B22/$B$10,1) -> 1 | D22: =B22/(C22*$B$10) -> 0.0035225049 | E22: =C22*$B$7 -> 1095 | F22: =E22/A22 -> 109.5 | G22: =A22*$B$14 -> 26.064 | H22: =$B$14 -> 2.6064 | I22: =IF(E22<G22,"Local","API") -> API | J22: =E22/G22 -> 42.011971
A23: 25 | B23: =A23*$B$13 -> 81000000 | C23: =CEILING(B23/$B$10,1) -> 1 | D23: =B23/(C23*$B$10) -> 0.0088062622 | E23: =C23*$B$7 -> 1095 | F23: =E23/A23 -> 43.8 | G23: =A23*$B$14 -> 65.16 | H23: =$B$14 -> 2.6064 | I23: =IF(E23<G23,"Local","API") -> API | J23: =E23/G23 -> 16.804788
A24: 50 | B24: =A24*$B$13 -> 162000000 | C24: =CEILING(B24/$B$10,1) -> 1 | D24: =B24/(C24*$B$10) -> 0.017612524 | E24: =C24*$B$7 -> 1095 | F24: =E24/A24 -> 21.9 | G24: =A24*$B$14 -> 130.32 | H24: =$B$14 -> 2.6064 | I24: =IF(E24<G24,"Local","API") -> API | J24: =E24/G24 -> 8.4023941
A25: 100 | B25: =A25*$B$13 -> 324000000 | C25: =CEILING(B25/$B$10,1) -> 1 | D25: =B25/(C25*$B$10) -> 0.035225049 | E25: =C25*$B$7 -> 1095 | F25: =E25/A25 -> 10.95 | G25: =A25*$B$14 -> 260.64 | H25: =$B$14 -> 2.6064 | I25: =IF(E25<G25,"Local","API") -> API | J25: =E25/G25 -> 4.2011971
A26: 250 | B26: =A26*$B$13 -> 810000000 | C26: =CEILING(B26/$B$10,1) -> 1 | D26: =B26/(C26*$B$10) -> 0.088062622 | E26: =C26*$B$7 -> 1095 | F26: =E26/A26 -> 4.38 | G26: =A26*$B$14 -> 651.6 | H26: =$B$14 -> 2.6064 | I26: =IF(E26<G26,"Local","API") -> API | J26: =E26/G26 -> 1.6804788
A27: 334 | B27: =A27*$B$13 -> 1082160000 | C27: =CEILING(B27/$B$10,1) -> 1 | D27: =B27/(C27*$B$10) -> 0.11765166 | E27: =C27*$B$7 -> 1095 | F27: =E27/A27 -> 3.2784431 | G27: =A27*$B$14 -> 870.5376 | H27: =$B$14 -> 2.6064 | I27: =IF(E27<G27,"Local","API") -> API | J27: =E27/G27 -> 1.2578434
A28: 420 | B28: =A28*$B$13 -> 1360800000 | C28: =CEILING(B28/$B$10,1) -> 1 | D28: =B28/(C28*$B$10) -> 0.14794521 | E28: =C28*$B$7 -> 1095 | F28: =E28/A28 -> 2.6071429 | G28: =A28*$B$14 -> 1094.688 | H28: =$B$14 -> 2.6064 | I28: =IF(E28<G28,"Local","API") -> API | J28: =E28/G28 -> 1.000285
A29: 500 | B29: =A29*$B$13 -> 1620000000 | C29: =CEILING(B29/$B$10,1) -> 1 | D29: =B29/(C29*$B$10) -> 0.17612524 | E29: =C29*$B$7 -> 1095 | F29: =E29/A29 -> 2.19 | G29: =A29*$B$14 -> 1303.2 | H29: =$B$14 -> 2.6064 | I29: =IF(E29<G29,"Local","API") -> Local | J29: =E29/G29 -> 0.84023941
A30: 1000 | B30: =A30*$B$13 -> 3240000000 | C30: =CEILING(B30/$B$10,1) -> 1 | D30: =B30/(C30*$B$10) -> 0.35225049 | E30: =C30*$B$7 -> 1095 | F30: =E30/A30 -> 1.095 | G30: =A30*$B$14 -> 2606.4 | H30: =$B$14 -> 2.6064 | I30: =IF(E30<G30,"Local","API") -> Local | J30: =E30/G30 -> 0.42011971
... A34: 12074 | B34: =A34*$B$13 -> 39119760000 | C34: =CEILING(B34/$B$10,1) -> 5 | D34: =B34/(C34*$B$10) -> 0.85061448 | E34: =C34*$B$7 -> 5475 | F34: =E34/A34 -> 0.4534537 | G34: =A34*$B$14 -> 31469.674 | H34: =$B$14 -> 2.6064 | I34: =IF(E34<G34,"Local","API") -> Local | J34: =E34/G34 -> 0.17397702
A36: WHY HARD DECISIONS STAY ON THE API
A37: Frontier local node (8x H100, BM.GPU.H100.8) $/GPU-hr | B37: 10 | C37: $/hr | D37: Source: OCI BM.GPU.H100.8 list ~$10/GPU-hr
A38: ... 8-GPU node fixed floor ($/mo) | B38: =B37*8*B6 -> 58400 | C38: $/mo
A39: Hard-decision API spend at 12,074 shards ($/mo) | B39: ='Agent Cost'!$H$6*12074 -> 16843.23 | C39: $/mo
A40: Frontier self-host floor exceeds the entire hard-decision API bill until the tree is enormous,
A41: and open-weight quality may still lag Opus. Keep the low-volume frontier tier on the API.
A43: BLENDED AGENT COST: API-only vs local-routine
A44: Scenario | B44: a, S=334 | C44: a, S=12,074 | E44: Full-Auto floor @12,074
A45: API-only (flat a) | B45: ='Agent Cost'!$H$8 -> 4.1664 | C45: ='Agent Cost'!$H$8 -> 4.1664 | E45: ='Mgmt Assumptions'!$B$16+'Mgmt Assumptions'!$B$17+'Agent Cost'!$H$8*12074 -> 80305.114
A46: Local routine + API frontier | B46: =F27+'Agent Cost'!$H$6+'Agent Cost'!$H$7 -> 4.8384431 | C46: =F34+'Agent Cost'!$H$6+'Agent Cost'!$H$7 -> 2.0134537 | E46: ='Mgmt Assumptions'!$B$16+'Mgmt Assumptions'!$B$17+E34+('Agent Cost'!$H$6+'Agent Cost'!$H$7)*12074 -> 54310.44
A47: Note: at S=334 local routine is WORSE than API (GPU underused) -> use API; switch to local above the break-even.
A49: Reading this tab:
...

Sheet Algorithmic vs LLM
A1: Algorithmic Control vs LLM — the missing regime
A2: Most shard-tree decisions are deterministic (split at alpha*, demote on empty fund, provision on capacity). The LLM is the EXCEPTION tier, not the control plane.
A4: TIER 0 — ALGORITHMIC CONTROL PLANE (no model)
A5: Control-plane eng + tooling ($/mo) | B5: 25000 | C5: $/mo | D5: build/maintain operators, reconcilers, threshold policies; overlaps the agent platform
A6: Shards / SRE, algorithmic + human escalation | B6: 150 | C6: shards/SRE | D6: plane removes toil; humans still field EVERY ambiguous + physical case
A7: Per-shard control-loop cost ($/shard-mo) | B7: 0 | C7: $/shard | D7: CPU cycles on existing nodes; negligible vs inference
A9: TIER 1 — LLM ESCALATION (priced on the RESIDUAL only)
A10: Deterministic fraction delta (rules handle) | B10: 0.95 | D10: split/demote/provision/threshold-health are rule-based
A11: LLM inference if it handled ALL decisions ($/shard) | B11: ='Agent Cost'!$H$5+'Agent Cost'!$H$6 -> 4.0014 | C11: $/shard | D11: routine+hard from Agent Cost (provisioning is deterministic, dropped)
A12: LLM inference on residual a_resid ($/shard) | B12: =(1-B10)*B11 -> 0.20007 | C12: $/shard | D12: (1-delta) x all-decision inference
A13: LLM-specific platform on top of Tier 0 ($/mo) | B13: 8000 | C13: $/mo | D13: evals, guardrails, model-ops; the algo plane's actuators are shared
A14: Shards / SRE, three-tier (algo+LLM+human) | B14: 300 | C14: shards/SRE | D14: LLM absorbs ambiguous-but-software-resolvable cases -> ~2x human reach vs Tier-0-only
A16: DECISION ROUTING (per shard-month)
A17: Total decisions / shard-mo | B17: ='Agent Cost'!$B$5+'Agent Cost'!$B$6+'Agent Cost'!$B$7 -> 726.5 | C17: count | D17: routine checks + hard + provisioning
A18: handled deterministically (free) | B18: =B10*B17 -> 690.175 | C18: count
A19: escalated beyond the rules | B19: =(1-B10)*B17 -> 36.325 | C19: count
A21: Shards S | B21: DevOps (no auto) | C21: Algo full-auto (floor) | D21: Algo + human (no LLM) | E21: Three-tier (algo+LLM+human) | F21: LLM full-auto (ref, all-LLM) | G21: Feasible best | H21: 3-tier vs Algo+human
A22: 1 | B22: ='Mgmt Assumptions'!$B$7*MAX('Mgmt Assumptions'!$B$9,CEILING(A22/'Mgmt Assumptions'!$B$8,1)) -> 40000 | C22: =$B$5+'Mgmt Assumptions'!$B$17+$B$7*A22 -> 27000 | D22: =$B$5+$B$7*A22+'Mgmt Assumptions'!$B$7*MAX('Mgmt Assumptions'!$B$11,CEILING(A22/$B$6,1)) -> 45000 | E22: =$B$5+$B$13+$B$12*A22+'Mgmt Assumptions'!$B$7*MAX('Mgmt Assumptions'!$B$11,CEILING(A22/$B$14,1)) -> 53000.2 | F22: ='Mgmt Assumptions'!$B$16+'Mgmt Assumptions'!$B$17+'Agent Cost'!$H$8*A22 -> 30004.166 | G22: =IF(E22<D22,"Three-tier","Algo+human") -> Algo+human | H22: =E22-D22 -> 8000.2001
A23: 10 | B23: ='Mgmt Assumptions'!$B$7*MAX('Mgmt Assumptions'!$B$9,CEILING(A23/'Mgmt Assumptions'!$B$8,1)) -> 40000 | C23: =$B$5+'Mgmt Assumptions'!$B$17+$B$7*A23 -> 27000 | D23: =$B$5+$B$7*A23+'Mgmt Assumptions'!$B$7*MAX('Mgmt Assumptions'!$B$11,CEILING(A23/$B$6,1)) -> 45000 | E23: =$B$5+$B$13+$B$12*A23+'Mgmt Assumptions'!$B$7*MAX('Mgmt Assumptions'!$B$11,CEILING(A23/$B$14,1)) -> 53002.001 | F23: ='Mgmt Assumptions'!$B$16+'Mgmt Assumptions'!$B$17+'Agent Cost'!$H$8*A23 -> 30041.664 | G23: =IF(E23<D23,"Three-tier","Algo+human") -> Algo+human | H23: =E23-D23 -> 8002.0007
A24: 50 | B24: ='Mgmt Assumptions'!$B$7*MAX('Mgmt Assumptions'!$B$9,CEILING(A24/'Mgmt Assumptions'!$B$8,1)) -> 40000 | C24: =$B$5+'Mgmt Assumptions'!$B$17+$B$7*A24 -> 27000 | D24: =$B$5+$B$7*A24+'Mgmt Assumptions'!$B$7*MAX('Mgmt Assumptions'!$B$11,CEILING(A24/$B$6,1)) -> 45000 | E24: =$B$5+$B$13+$B$12*A24+'Mgmt Assumptions'!$B$7*MAX('Mgmt Assumptions'!$B$11,CEILING(A24/$B$14,1)) -> 53010.003 | F24: ='Mgmt Assumptions'!$B$16+'Mgmt Assumptions'!$B$17+'Agent Cost'!$H$8*A24 -> 30208.32 | G24: =IF(E24<D24,"Three-tier","Algo+human") -> Algo+human | H24: =E24-D24 -> 8010.0035
A25: 100 | B25: ='Mgmt Assumptions'!$B$7*MAX('Mgmt Assumptions'!$B$9,CEILING(A25/'Mgmt Assumptions'!$B$8,1)) -> 80000 | C25: =$B$5+'Mgmt Assumptions'!$B$17+$B$7*A25 -> 27000 | D25: =$B$5+$B$7*A25+'Mgmt Assumptions'!$B$7*MAX('Mgmt Assumptions'!$B$11,CEILING(A25/$B$6,1)) -> 45000 | E25: =$B$5+$B$13+$B$12*A25+'Mgmt Assumptions'!$B$7*MAX('Mgmt Assumptions'!$B$11,CEILING(A25/$B$14,1)) -> 53020.007 | F25: ='Mgmt Assumptions'!$B$16+'Mgmt Assumptions'!$B$17+'Agent Cost'!$H$8*A25 -> 30416.64 | G25: =IF(E25<D25,"Three-tier","Algo+human") -> Algo+human | H25: =E25-D25 -> 8020.007
A26: 150 | B26: ='Mgmt Assumptions'!$B$7*MAX('Mgmt Assumptions'!$B$9,CEILING(A26/'Mgmt Assumptions'!$B$8,1)) -> 100000 | C26: =$B$5+'Mgmt Assumptions'!$B$17+$B$7*A26 -> 27000 | D26: =$B$5+$B$7*A26+'Mgmt Assumptions'!$B$7*MAX('Mgmt Assumptions'!$B$11,CEILING(A26/$B$6,1)) -> 45000 | E26: =$B$5+$B$13+$B$12*A26+'Mgmt Assumptions'!$B$7*MAX('Mgmt Assumptions'!$B$11,CEILING(A26/$B$14,1)) -> 53030.01 | F26: ='Mgmt Assumptions'!$B$16+'Mgmt Assumptions'!$B$17+'Agent Cost'!$H$8*A26 -> 30624.96 | G26: =IF(E26<D26,"Three-tier","Algo+human") -> Algo+human | H26: =E26-D26 -> 8030.0105
A27: 250 | B27: ='Mgmt Assumptions'!$B$7*MAX('Mgmt Assumptions'!$B$9,CEILING(A27/'Mgmt Assumptions'!$B$8,1)) -> 180000 | C27: =$B$5+'Mgmt Assumptions'!$B$17+$B$7*A27 -> 27000 | D27: =$B$5+$B$7*A27+'Mgmt Assumptions'!$B$7*MAX('Mgmt Assumptions'!$B$11,CEILING(A27/$B$6,1)) -> 65000 | E27: =$B$5+$B$13+$B$12*A27+'Mgmt Assumptions'!$B$7*MAX('Mgmt Assumptions'!$B$11,CEILING(A27/$B$14,1)) -> 53050.018 | F27: ='Mgmt Assumptions'!$B$16+'Mgmt Assumptions'!$B$17+'Agent Cost'!$H$8*A27 -> 31041.6 | G27: =IF(E27<D27,"Three-tier","Algo+human") -> Three-tier | H27: =E27-D27 -> -11949.983
A28: 500 | B28: ='Mgmt Assumptions'!$B$7*MAX('Mgmt Assumptions'!$B$9,CEILING(A28/'Mgmt Assumptions'!$B$8,1)) -> 340000 | C28: =$B$5+'Mgmt Assumptions'!$B$17+$B$7*A28 -> 27000 | D28: =$B$5+$B$7*A28+'Mgmt Assumptions'!$B$7*MAX('Mgmt Assumptions'!$B$11,CEILING(A28/$B$6,1)) -> 105000 | E28: =$B$5+$B$13+$B$12*A28+'Mgmt Assumptions'!$B$7*MAX('Mgmt Assumptions'!$B$11,CEILING(A28/$B$14,1)) -> 73100.035 | F28: ='Mgmt Assumptions'!$B$16+'Mgmt Assumptions'!$B$17+'Agent Cost'!$H$8*A28 -> 32083.2 | G28: =IF(E28<D28,"Three-tier","Algo+human") -> Three-tier | H28: =E28-D28 -> -31899.965
A29: 1000 | B29: ='Mgmt Assumptions'!$B$7*MAX('Mgmt Assumptions'!$B$9,CEILING(A29/'Mgmt Assumptions'!$B$8,1)) -> 680000 | C29: =$B$5+'Mgmt Assumptions'!$B$17+$B$7*A29 -> 27000 | D29: =$B$5+$B$7*A29+'Mgmt Assumptions'!$B$7*MAX('Mgmt Assumptions'!$B$11,CEILING(A29/$B$6,1)) -> 165000 | E29: =$B$5+$B$13+$B$12*A29+'Mgmt Assumptions'!$B$7*MAX('Mgmt Assumptions'!$B$11,CEILING(A29/$B$14,1)) -> 113200.07 | F29: ='Mgmt Assumptions'!$B$16+'Mgmt Assumptions'!$B$17+'Agent Cost'!$H$8*A29 -> 34166.4 | G29: =IF(E29<D29,"Three-tier","Algo+human") -> Three-tier | H29: =E29-D29 -> -51799.93
A30: 2500 | B30: ='Mgmt Assumptions'!$B$7*MAX('Mgmt Assumptions'!$B$9,CEILING(A30/'Mgmt Assumptions'!$B$8,1)) -> 1680000 | C30: =$B$5+'Mgmt Assumptions'!$B$17+$B$7*A30 -> 27000 | D30: =$B$5+$B$7*A30+'Mgmt Assumptions'!$B$7*MAX('Mgmt Assumptions'!$B$11,CEILING(A30/$B$6,1)) -> 365000 | E30: =$B$5+$B$13+$B$12*A30+'Mgmt Assumptions'!$B$7*MAX('Mgmt Assumptions'!$B$11,CEILING(A30/$B$14,1)) -> 213500.17 | F30: ='Mgmt Assumptions'!$B$16+'Mgmt Assumptions'!$B$17+'Agent Cost'!$H$8*A30 -> 40416 | G30: =IF(E30<D30,"Three-tier","Algo+human") -> Three-tier | H30: =E30-D30 -> -151499.83
A31: 5000 | B31: ='Mgmt Assumptions'!$B$7*MAX('Mgmt Assumptions'!$B$9,CEILING(A31/'Mgmt Assumptions'!$B$8,1)) -> 3340000 | C31: =$B$5+'Mgmt Assumptions'!$B$17+$B$7*A31 -> 27000 | D31: =$B$5+$B$7*A31+'Mgmt Assumptions'!$B$7*MAX('Mgmt Assumptions'!$B$11,CEILING(A31/$B$6,1)) -> 705000 | E31: =$B$5+$B$13+$B$12*A31+'Mgmt Assumptions'!$B$7*MAX('Mgmt Assumptions'!$B$11,CEILING(A31/$B$14,1)) -> 374000.35 | F31: ='Mgmt Assumptions'!$B$16+'Mgmt Assumptions'!$B$17+'Agent Cost'!$H$8*A31 -> 50832 | G31: =IF(E31<D31,"Three-tier","Algo+human") -> Three-tier | H31: =E31-D31 -> -330999.65
A32: 12074 | B32: ='Mgmt Assumptions'!$B$7*MAX('Mgmt Assumptions'!$B$9,CEILING(A32/'Mgmt Assumptions'!$B$8,1)) -> 8060000 | C32: =$B$5+'Mgmt Assumptions'!$B$17+$B$7*A32 -> 27000 | D32: =$B$5+$B$7*A32+'Mgmt Assumptions'!$B$7*MAX('Mgmt Assumptions'!$B$11,CEILING(A32/$B$6,1)) -> 1645000 | E32: =$B$5+$B$13+$B$12*A32+'Mgmt Assumptions'!$B$7*MAX('Mgmt Assumptions'!$B$11,CEILING(A32/$B$14,1)) -> 855415.65 | F32: ='Mgmt Assumptions'!$B$16+'Mgmt Assumptions'!$B$17+'Agent Cost'!$H$8*A32 -> 80305.114 | G32: =IF(E32<D32,"Three-tier","Algo+human") -> Three-tier | H32: =E32-D32 -> -789584.35
A34: VERDICT
A35: Algorithmic full-auto floor (flat, any S) | C35: =$B$5+'Mgmt Assumptions'!$B$17+$B$7*1 -> 27000
A36: Three-tier overtakes Algo+human above ~ (shards) | C36: =INDEX(A22:A32,MATCH(TRUE(),INDEX(E22:E32<D22:D32,0),0)) -> 250
A37: LLM residual inference vs all-LLM inference | C37: =B12/'Agent Cost'!$H$8 -> 0.048019873
A39: What this tab adds (and the rest of the model lacked):
A40: - A PURE ALGORITHMIC regime. Most shard-tree decisions are deterministic: split when alpha>alpha*, demote when the
A41: rent fund empties, provision when capacity is hit, remediate when a health metric leaves its band. These are threshold
A42: tests and B-tree range handoffs (per the rent note's R1-R5 rules) -- a control plane, not a chat model.
A43: - Its cost: a fixed control-plane engineering charge and ~ZERO marginal per shard. The algorithmic full-auto FLOOR is
A44: flat at ~$27k/mo for ANY tree size -- the true automation floor, below every LLM regime, because it buys no inference.
A45: - The CORRECT role of the LLM: an escalation tier ABOVE the algo plane, priced on the residual (~5%) of decisions the
A46: rules don't cover -- not on all 726 decisions/shard-mo. That cuts modelled LLM inference ~20x (a_resid ~ $0.20/shard).
...
