Workbook

Sheet Assumptions
A1: F1R3FLY — Sharding Economics Model
A2: Assumptions & levers. All downstream tabs are formula-linked to this sheet.
A3: Legend: | B3: Blue = input / lever | C3: Black = formula | D3: Green = cross-sheet link
A5: INFRASTRUCTURE (OCI list prices, Q1–Q2 2026)
A6: Nodes per shard | B6: 10 | C6: nodes
A7: Cores (OCPU) per node | B7: 16 | C7: OCPU
A8: Memory per node | B8: 16 | C8: GB
A9: Storage per node | B9: 2 | C9: TB
A10: Hours per month | B10: 730 | C10: h
A11: Compute rate | B11: 0.025 | C11: $/OCPU-hr
A12: Memory rate | B12: 0.0015 | C12: $/GB-hr
A13: Block storage rate | B13: 0.0255 | C13: $/GB-mo
A14: Ops / overhead | B14: 0.15 | C14: %
A15: Per-residual footprint | B15: 1 | C15: KB
A16: Residuals per deploy | B16: 5 | C16: count
A18: CAPACITY & PACKING
A19: Dense capacity per shard | B19: 30000000 | C19: tx/mo
A20: Headroom capacity per shard | B20: 20000000 | C20: tx/mo
A21: Hot slots per shard | B21: =B6*B8*1000000000/(B15*1000) -> 160000000 | C21: slots
A23: ADVERTISING
A24: Display CPM | B24: 3 | C24: $/1000 impr
A25: Per-impression value | B25: =B24/1000 -> 0.003 | C25: $/impr
A27: SECTOR FEES (r_tx, blended $/transaction)
A28: AI | B28: 0.01 | C28: $/tx
A29: Fintech | B29: 0.25 | C29: $/tx
A30: Music | B30: 0.0003 | C30: $/play
A31: Medical — $/patient/month (R) | B31: 1 | C31: $/pt-mo
A32: Medical — tx/patient/month (τ) | B32: 50 | C32: tx/pt-mo
A33: Medical — implied $/tx | B33: =B31/B32 -> 0.02 | C33: $/tx
A35: COMPLIANCE MULTIPLIERS
A36: AI | B36: 1.2 | C36: x
A37: Music | B37: 1 | C37: x
A38: Biotech | B38: 1.5 | C38: x
A39: Fintech | B39: 2.5 | C39: x
A40: Medical | B40: 4 | C40: x
A42: BANDWIDTH (OCI egress; set to 0 to model reported free-egress)
A43: Internet egress | B43: 0.0085 | C43: $/GB
A44: Inter-region egress | B44: 0.005 | C44: $/GB
A45: CDN / edge egress | B45: 0.04 | C45: $/GB
A46: Free egress tier | B46: 10 | C46: TB/mo
...

Sheet Rent Cost Model
A1: Rent — Monthly Network Cost of One Shard
A2: Builds the all-in monthly cost C that rent amortizes. Linked to Assumptions.
A4: Resource | B4: Quantity | C4: Unit price ($) | D4: Monthly cost ($)
A5: Compute (OCPU) | B5: =Assumptions!$B$6*Assumptions!$B$7 -> 160 | C5: =Assumptions!$B$11 -> 0.025 | D5: =B5*C5*Assumptions!$B$10 -> 2920
A6: Memory (GB) | B6: =Assumptions!$B$6*Assumptions!$B$8 -> 160 | C6: =Assumptions!$B$12 -> 0.0015 | D6: =B6*C6*Assumptions!$B$10 -> 175.2
A7: Block storage (GB) | B7: =Assumptions!$B$6*Assumptions!$B$9*1024 -> 20480 | C7: =Assumptions!$B$13 -> 0.0255 | D7: =B7*C7 -> 522.24
A8: Egress (<=10TB free) | B8: 0 | C8: 0 | D8: 0
A9: Subtotal | D9: =SUM(D5:D8) -> 3617.44
A10: Ops / overhead | C10: =Assumptions!$B$14 -> 0.15 | D10: =D9*C10 -> 542.616
A11: All-in monthly cost C | D11: =D9+D10 -> 4160.056
A13: Per-payload cost at dense packing | D13: =D11/Assumptions!$B$19 -> 0.00013866853

Sheet Rent Density
A1: Rent — Tenant Density, Base Rent & Split Threshold
A2: Standing tenants and base rent versus client deployment rate.
A4: Deploys / day | B4: Standing tenants | C4: Hot-table occupancy | D4: Base rent ($/tenant-mo)
A5: 100 | B5: =A5*30*Assumptions!$B$16 -> 15000 | C5: =B5/Assumptions!$B$21 -> 9.375e-05 | D5: ='Rent Cost Model'!$D$11/B5 -> 0.27733707
A6: 1000 | B6: =A6*30*Assumptions!$B$16 -> 150000 | C6: =B6/Assumptions!$B$21 -> 0.0009375 | D6: ='Rent Cost Model'!$D$11/B6 -> 0.027733707
A7: 10000 | B7: =A7*30*Assumptions!$B$16 -> 1500000 | C7: =B7/Assumptions!$B$21 -> 0.009375 | D7: ='Rent Cost Model'!$D$11/B7 -> 0.0027733707
A8: 100000 | B8: =A8*30*Assumptions!$B$16 -> 15000000 | C8: =B8/Assumptions!$B$21 -> 0.09375 | D8: ='Rent Cost Model'!$D$11/B8 -> 0.00027733707
A9: 1000000 | B9: =A9*30*Assumptions!$B$16 -> 150000000 | C9: =B9/Assumptions!$B$21 -> 0.9375 | D9: ='Rent Cost Model'!$D$11/B9 -> 2.7733707e-05
A11: SPLIT THRESHOLD (when a shard should divide)
A12: Split overhead K (probe-equiv) | B12: 50
A13: Conventional open addressing α* | B13: =1-1/B12 -> 0.98
A14: Elastic constant C | B14: 1
A15: Elastic hashing α* (FKK 2025) | B15: =1-0.5*EXP(-B12/B14) -> 1

Sheet Rent Solvency
A1: Rent — Solvency Grid
A2: Net rent = base rent(D) − access fee. Green = self-sustaining (surplus).
A4: Deploys/day \ fee | B4: 0 | C4: 0.0001 | D4: 0.001 | E4: 0.01 | F4: 0.1
A5: 100 | B5: ='Rent Density'!$D$5-B$4 -> 0.27733707 | C5: ='Rent Density'!$D$5-C$4 -> 0.27723707 | D5: ='Rent Density'!$D$5-D$4 -> 0.27633707 | E5: ='Rent Density'!$D$5-E$4 -> 0.26733707 | F5: ='Rent Density'!$D$5-F$4 -> 0.17733707
A6: 1000 | B6: ='Rent Density'!$D$6-B$4 -> 0.027733707 | C6: ='Rent Density'!$D$6-C$4 -> 0.027633707 | D6: ='Rent Density'!$D$6-D$4 -> 0.026733707 | E6: ='Rent Density'!$D$6-E$4 -> 0.017733707 | F6: ='Rent Density'!$D$6-F$4 -> -0.072266293
A7: 10000 | B7: ='Rent Density'!$D$7-B$4 -> 0.0027733707 | C7: ='Rent Density'!$D$7-C$4 -> 0.0026733707 | D7: ='Rent Density'!$D$7-D$4 -> 0.0017733707 | E7: ='Rent Density'!$D$7-E$4 -> -0.0072266293 | F7: ='Rent Density'!$D$7-F$4 -> -0.097226629
A8: 100000 | B8: ='Rent Density'!$D$8-B$4 -> 0.00027733707 | C8: ='Rent Density'!$D$8-C$4 -> 0.00017733707 | D8: ='Rent Density'!$D$8-D$4 -> -0.00072266293 | E8: ='Rent Density'!$D$8-E$4 -> -0.0097226629 | F8: ='Rent Density'!$D$8-F$4 -> -0.099722663
A9: 1000000 | B9: ='Rent Density'!$D$9-B$4 -> 2.7733707e-05 | C9: ='Rent Density'!$D$9-C$4 -> -7.2266293e-05 | D9: ='Rent Density'!$D$9-D$4 -> -0.00097226629 | E9: ='Rent Density'!$D$9-E$4 -> -0.0099722663 | F9: ='Rent Density'!$D$9-F$4 -> -0.099972266

Sheet AI
A1: AI (ASI Alliance) — the growth engine
A2: Unbounded, machine-generated volume. Anchors the rollout.
A4: PARAMETERS
A5: Fee r_tx ($/tx) | B5: =Assumptions!$B$28 -> 0.01
A6: Compliance multiplier | B6: =Assumptions!$B$36 -> 1.2
A7: All-in cost C ($/shard-mo) | B7: ='Rent Cost Model'!$D$11 -> 4160.056
A8: Effective cost C_eff ($/shard-mo) | B8: =B6*B7 -> 4992.0672
A9: Dense capacity (tx/shard-mo) | B9: =Assumptions!$B$19 -> 30000000
A10: Transactions per agent / month | B10: 10000
A11: Break-even traffic (tx/mo) | B11: =B8/B5 -> 499206.72
A12: Break-even load (% of shard) | B12: =B11/B9 -> 0.016640224
A14: Year | B14: Agents | C14: Monthly tx | D14: Shards | E14: Cost ($) | F14: Revenue ($) | G14: Margin
A15: 1 | B15: 100 | C15: =B15*$B$10 -> 1000000 | D15: =CEILING(C15/$B$9,1) -> 1 | E15: =D15*$B$8 -> 4992.0672 | F15: =C15*$B$5 -> 10000 | G15: =F15/E15 -> 2.0031782
A16: 2 | B16: 1000 | C16: =B16*$B$10 -> 10000000 | D16: =CEILING(C16/$B$9,1) -> 1 | E16: =D16*$B$8 -> 4992.0672 | F16: =C16*$B$5 -> 100000 | G16: =F16/E16 -> 20.031782
A17: 3 | B17: 10000 | C17: =B17*$B$10 -> 100000000 | D17: =CEILING(C17/$B$9,1) -> 4 | E17: =D17*$B$8 -> 19968.269 | F17: =C17*$B$5 -> 1000000 | G17: =F17/E17 -> 50.079454
A18: 4 | B18: 100000 | C18: =B18*$B$10 -> 1000000000 | D18: =CEILING(C18/$B$9,1) -> 34 | E18: =D18*$B$8 -> 169730.28 | F18: =C18*$B$5 -> 10000000 | G18: =F18/E18 -> 58.917005
A19: 5 | B19: 1000000 | C19: =B19*$B$10 -> 10000000000 | D19: =CEILING(C19/$B$9,1) -> 334 | E19: =D19*$B$8 -> 1667350.4 | F19: =C19*$B$5 -> 100000000 | G19: =F19/E19 -> 59.975394

Sheet Fintech
A1: Fintech (Boring Financial) — the density engine
A2: Highest revenue density. Fee is bimodal: model instrument classes separately.
A4: PARAMETERS
A5: Fee r_tx ($/tx) | B5: =Assumptions!$B$29 -> 0.25
A6: Compliance multiplier | B6: =Assumptions!$B$39 -> 2.5
A7: All-in cost C ($/shard-mo) | B7: ='Rent Cost Model'!$D$11 -> 4160.056
A8: Effective cost C_eff ($/shard-mo) | B8: =B6*B7 -> 10400.14
A9: Headroom capacity (tx/shard-mo) | B9: =Assumptions!$B$20 -> 20000000
A10: Break-even traffic (tx/mo) | B10: =B8/B5 -> 41600.56
A11: Break-even load (% of shard) | B11: =B10/B9 -> 0.002080028
A13: Year | B13: Monthly tx | C13: Shards | D13: Cost ($) | E13: Revenue ($) | F13: Margin
A14: 1 | B14: 50000 | C14: =CEILING(B14/$B$9,1) -> 1 | D14: =C14*$B$8 -> 10400.14 | E14: =B14*$B$5 -> 12500 | F14: =E14/D14 -> 1.2019069
A15: 2 | B15: 500000 | C15: =CEILING(B15/$B$9,1) -> 1 | D15: =C15*$B$8 -> 10400.14 | E15: =B15*$B$5 -> 125000 | F15: =E15/D15 -> 12.019069
A16: 3 | B16: 5000000 | C16: =CEILING(B16/$B$9,1) -> 1 | D16: =C16*$B$8 -> 10400.14 | E16: =B16*$B$5 -> 1250000 | F16: =E16/D16 -> 120.19069
A17: 4 | B17: 50000000 | C17: =CEILING(B17/$B$9,1) -> 3 | D17: =C17*$B$8 -> 31200.42 | E17: =B17*$B$5 -> 12500000 | F17: =E17/D17 -> 400.63563
A18: 5 | B18: 500000000 | C18: =CEILING(B18/$B$9,1) -> 25 | D18: =C18*$B$8 -> 260003.5 | E18: =B18*$B$5 -> 125000000 | F18: =E18/D18 -> 480.76276

Sheet Medical
A1: Medical (VA) — the cohort-capped annuity
A2: Logistic growth, hard cohort ceiling, highest assurance. Deploys last.
A4: PARAMETERS
A5: Enrolled cohort (veterans) | B5: 9100000
A6: Target share | B6: 0.8
A7: Target patients | B7: =B5*B6 -> 7280000
A8: $/patient/month (R) | B8: =Assumptions!$B$31 -> 1
A9: tx/patient/month (τ) | B9: =Assumptions!$B$32 -> 50
A10: Compliance multiplier | B10: =Assumptions!$B$40 -> 4
A11: All-in cost C ($/shard-mo) | B11: ='Rent Cost Model'!$D$11 -> 4160.056
A12: Effective cost C_eff ($/shard-mo) | B12: =B11*B10 -> 16640.224
A13: Headroom capacity (tx/shard-mo) | B13: =Assumptions!$B$20 -> 20000000
A14: Break-even patients | B14: =B12/B8 -> 16640.224
A15: Patients per shard | B15: =B13/B9 -> 400000
A16: Break-even load (% of shard) | B16: =B14/B15 -> 0.04160056
A18: Year | B18: Patients | C18: Monthly tx | D18: Shards | E18: Cost ($) | F18: Revenue ($) | G18: Margin | H18: Annual rev ($) | I18: Annual cost ($)
A19: 1 | B19: 7280 | C19: =B19*$B$9 -> 364000 | D19: =CEILING(C19/$B$13,1) -> 1 | E19: =D19*$B$12 -> 16640.224 | F19: =B19*$B$8 -> 7280 | G19: =F19/E19 -> 0.43749411 | H19: =F19*12 -> 87360 | I19: =E19*12 -> 199682.69
A20: 2 | B20: 72800 | C20: =B20*$B$9 -> 3640000 | D20: =CEILING(C20/$B$13,1) -> 1 | E20: =D20*$B$12 -> 16640.224 | F20: =B20*$B$8 -> 72800 | G20: =F20/E20 -> 4.3749411 | H20: =F20*12 -> 873600 | I20: =E20*12 -> 199682.69
A21: 3 | B21: 728000 | C21: =B21*$B$9 -> 36400000 | D21: =CEILING(C21/$B$13,1) -> 2 | E21: =D21*$B$12 -> 33280.448 | F21: =B21*$B$8 -> 728000 | G21: =F21/E21 -> 21.874706 | H21: =F21*12 -> 8736000 | I21: =E21*12 -> 399365.38
A22: 4 | B22: =$B$7 -> 7280000 | C22: =B22*$B$9 -> 364000000 | D22: =CEILING(C22/$B$13,1) -> 19 | E22: =D22*$B$12 -> 316164.26 | F22: =B22*$B$8 -> 7280000 | G22: =F22/E22 -> 23.026006 | H22: =F22*12 -> 87360000 | I22: =E22*12 -> 3793971.1
A23: 5 | B23: =$B$7 -> 7280000 | C23: =B23*$B$9 -> 364000000 | D23: =CEILING(C23/$B$13,1) -> 19 | E23: =D23*$B$12 -> 316164.26 | F23: =B23*$B$8 -> 7280000 | G23: =F23/E23 -> 23.026006 | H23: =F23*12 -> 87360000 | I23: =E23*12 -> 3793971.1
A24: 6 | B24: =$B$7 -> 7280000 | C24: =B24*$B$9 -> 364000000 | D24: =CEILING(C24/$B$13,1) -> 19 | E24: =D24*$B$12 -> 316164.26 | F24: =B24*$B$8 -> 7280000 | G24: =F24/E24 -> 23.026006 | H24: =F24*12 -> 87360000 | I24: =E24*12 -> 3793971.1
A25: 7 | B25: =$B$7 -> 7280000 | C25: =B25*$B$9 -> 364000000 | D25: =CEILING(C25/$B$13,1) -> 19 | E25: =D25*$B$12 -> 316164.26 | F25: =B25*$B$8 -> 7280000 | G25: =F25/E25 -> 23.026006 | H25: =F25*12 -> 87360000 | I25: =E25*12 -> 3793971.1
A26: 8 | B26: =$B$7 -> 7280000 | C26: =B26*$B$9 -> 364000000 | D26: =CEILING(C26/$B$13,1) -> 19 | E26: =D26*$B$12 -> 316164.26 | F26: =B26*$B$8 -> 7280000 | G26: =F26/E26 -> 23.026006 | H26: =F26*12 -> 87360000 | I26: =E26*12 -> 3793971.1
A27: 9 | B27: =$B$7 -> 7280000 | C27: =B27*$B$9 -> 364000000 | D27: =CEILING(C27/$B$13,1) -> 19 | E27: =D27*$B$12 -> 316164.26 | F27: =B27*$B$8 -> 7280000 | G27: =F27/E27 -> 23.026006 | H27: =F27*12 -> 87360000 | I27: =E27*12 -> 3793971.1
A28: 10 | B28: =$B$7 -> 7280000 | C28: =B28*$B$9 -> 364000000 | D28: =CEILING(C28/$B$13,1) -> 19 | E28: =D28*$B$12 -> 316164.26 | F28: =B28*$B$8 -> 7280000 | G28: =F28/E28 -> 23.026006 | H28: =F28*12 -> 87360000 | I28: =E28*12 -> 3793971.1
A29: Decade total | H29: =SUM(H19:H28) -> 621216960 | I29: =SUM(I19:I28) -> 27356528

Sheet Music
A1: Music — the cold-tail fill
A2: Ten-artist indie stable. High margin but roster-fragile; ideal as packing, not anchor.
A4: PARAMETERS
A5: Artists in stable | B5: 10
A6: Followers per artist | B6: 1000000
A7: Plays per audient / month | B7: 10
A8: Total plays / month | B8: =B5*B6*B7 -> 100000000
A9: Fee r_tx ($/play) | B9: =Assumptions!$B$30 -> 0.0003
A10: All-in cost C ($/shard-mo) | B10: ='Rent Cost Model'!$D$11 -> 4160.056
A11: Dense capacity (tx/shard-mo) | B11: =Assumptions!$B$19 -> 30000000
A12: Shards (per-play, on-chain) | B12: =CEILING(B8/B11,1) -> 4
A13: Cost ($/mo) | B13: =B12*B10 -> 16640.224
A14: Break-even fee ($/play) | B14: =B13/B8 -> 0.00016640224
A16: FEE SENSITIVITY (per-play, on-chain)
A17: Fee / play ($) | B17: Revenue ($) | C17: Cost ($) | D17: Margin
A18: 0.0001 | B18: =$B$8*A18 -> 10000 | C18: =$B$13 -> 16640.224 | D18: =B18/C18 -> 0.60095345
A19: 0.000166 | B19: =$B$8*A19 -> 16600 | C19: =$B$13 -> 16640.224 | D19: =B19/C19 -> 0.99758272
A20: 0.0003 | B20: =$B$8*A20 -> 30000 | C20: =$B$13 -> 16640.224 | D20: =B20/C20 -> 1.8028603
A21: 0.001 | B21: =$B$8*A21 -> 100000 | C21: =$B$13 -> 16640.224 | D21: =B21/C21 -> 6.0095345
A23: BATCHED SETTLEMENT ALTERNATIVE
A24: Batch ratio (plays : settlement) | B24: 100
A25: Batched tx / month | B25: =B8/B24 -> 1000000
A26: Batched shards | B26: =CEILING(B25/B11,1) -> 1
A27: Batched cost ($/mo) | B27: =B26*B10 -> 4160.056
A28: Effective take / settlement ($) | B28: 0.03
A29: Batched revenue ($/mo) | B29: =B25*B28 -> 30000
A30: Batched margin | B30: =B29/B27 -> 7.2114414

Sheet Web 2.0
A1: Web 2.0 — participatory advertising
A2: Users pay network cost in tokenised impressions; one impression covers ~20 payloads.
A4: PARAMETERS
A5: Per-payload cost ($) | B5: ='Rent Cost Model'!$D$13 -> 0.00013866853
A6: Display CPM ($) | B6: =Assumptions!$B$24 -> 3
A7: Per-impression value ($) | B7: =Assumptions!$B$25 -> 0.003
A8: Payloads covered per impression | B8: =B7/B5 -> 21.634324
A9: Dense capacity (tx/shard-mo) | B9: =Assumptions!$B$19 -> 30000000
A10: All-in cost C ($/shard-mo) | B10: ='Rent Cost Model'!$D$11 -> 4160.056
A12: Property | B12: Users | C12: Payloads/mo | D12: Shards | E12: Infra cost ($/mo) | F12: Payloads/user-mo | G12: Cost/user-mo ($) | H12: Break-even ads/user/day
A13: Gmail | B13: 1800000000 | C13: 3600000000000 | D13: =CEILING(C13/$B$9,1) -> 120000 | E13: =D13*$B$10 -> 499206720 | F13: =C13/B13 -> 2000 | G13: =F13*$B$5 -> 0.27733707 | H13: =(G13/$B$7)/30 -> 3.081523
A14: Maps | B14: 2000000000 | C14: 3000000000000 | D14: =CEILING(C14/$B$9,1) -> 100000 | E14: =D14*$B$10 -> 416005600 | F14: =C14/B14 -> 1500 | G14: =F14*$B$5 -> 0.2080028 | H14: =(G14/$B$7)/30 -> 2.3111422
A15: Docs | B15: 3000000000 | C15: 600000000000 | D15: =CEILING(C15/$B$9,1) -> 20000 | E15: =D15*$B$10 -> 83201120 | F15: =C15/B15 -> 200 | G15: =F15*$B$5 -> 0.027733707 | H15: =(G15/$B$7)/30 -> 0.3081523
A17: PRIVACY WEDGE & THIN-MARGIN ECONOMICS
A18: Gmail privacy slice (%) | B18: 0.01
A19: Wedge users | B19: =B13*B18 -> 18000000
A20: Wedge payloads/mo | B20: =C13*B18 -> 36000000000
A21: Wedge shards | B21: =CEILING(B20/B9,1) -> 1200
A22: Wedge infra ($/mo) | B22: =B21*B10 -> 4992067.2
A23: Per-payload take ($) | B23: 2e-05
A24: Gmail-scale monthly take ($) | B24: =C13*B23 -> 72000000

Sheet CAC
A1: Customer Acquisition — Wholesale (anchor) vs Retail (D2C)
A2: Court anchors, not heads. CAC/head = A / (population x conversion).
A4: BENCHMARKS & LEVERS
A5: Facebook D2C CAC ($/head) | B5: 50
A6: WhatsApp D2C CAC ($/head) | B6: 19
A7: Cross-market multiplier m | B7: 4
A9: Channel / anchor | B9: A ($) | C9: Population/anchor | D9: Conversion c | E9: Heads acquired | F9: CAC/head ($) | G9: x vs WhatsApp | H9: x vs Facebook
A10: Music — inbound | B10: 2000 | C10: 1000000 | D10: 0.1 | E10: =C10*D10 -> 100000 | F10: =B10/E10 -> 0.02 | G10: =$B$6/F10 -> 950 | H10: =$B$5/F10 -> 2500
A11: Music — mid | B11: 5000 | C11: 1000000 | D11: 0.05 | E11: =C11*D11 -> 50000 | F11: =B11/E11 -> 0.1 | G11: =$B$6/F11 -> 190 | H11: =$B$5/F11 -> 500
A12: Music — conservative | B12: 10000 | C12: 1000000 | D12: 0.01 | E12: =C12*D12 -> 10000 | F12: =B12/E12 -> 1 | G12: =$B$6/F12 -> 19 | H12: =$B$5/F12 -> 50
A13: Healthcare — mid hospital | B13: 500000 | C13: 1000000 | D13: 1 | E13: =C13*D13 -> 1000000 | F13: =B13/E13 -> 0.5 | G13: =$B$6/F13 -> 38 | H13: =$B$5/F13 -> 100
A14: VA — conservative | B14: 5000000 | C14: 9100000 | D14: 0.8 | E14: =C14*D14 -> 7280000 | F14: =B14/E14 -> 0.68681319 | G14: =$B$6/F14 -> 27.664 | H14: =$B$5/F14 -> 72.8
A15: VA — heavy gov. sale | B15: 20000000 | C15: 9100000 | D15: 0.8 | E15: =C15*D15 -> 7280000 | F15: =B15/E15 -> 2.7472527 | G15: =$B$6/F15 -> 6.916 | H15: =$B$5/F15 -> 18.2
A17: LTV & PAYBACK
A18: Channel | B18: CAC/head ($) | C18: LTV ($/head-mo) | D18: Payback (mo, 1 market) | E18: Eff. CAC w/ cross-mkt ($) | F18: Payback (mo, cross-mkt)
A19: Music (conservative) | B19: =F12 -> 1 | C19: =Music!$B$7*Music!$B$9 -> 0.003 | D19: =B19/C19 -> 333.33333 | E19: =B19/$B$7 -> 0.25 | F19: =B19/(C19*$B$7) -> 83.333333
A20: Healthcare (VA conservative) | B20: =F14 -> 0.68681319 | C20: =Assumptions!$B$31 -> 1 | D20: =B20/C20 -> 0.68681319 | E20: =B20/$B$7 -> 0.1717033 | F20: =B20/(C20*$B$7) -> 0.1717033
A22: Note: music's true cross-market LTV is dominated by direct artist sales (a $10 album at a 3% fee = $0.30), not 4x streaming; m is a coarse lever.

Sheet Connector
A1: Connector Shard — Cross-Shard Interchange
A2: Where F1R3FLY taxes value moving between shards. Revenue ~ volume x chi x fee.
A4: PARAMETERS
A5: Core cross-shard fee r_x ($/tx) | B5: 0.005
A6: Core effective χ | B6: 0.2
A7: Web 2.0 cross-shard fee ($/payload) | B7: 0.0005
A8: Web 2.0 effective χ | B8: 0.05
A9: Dense capacity (tx/shard-mo) | B9: =Assumptions!$B$19 -> 30000000
A10: All-in cost C ($/shard-mo) | B10: ='Rent Cost Model'!$D$11 -> 4160.056
A12: CONNECTABLE VOLUME (mature, linked from sector tabs)
A13: AI (year 5) | B13: =AI!$C$19 -> 10000000000
A14: Fintech (year 5) | B14: =Fintech!$B$18 -> 500000000
A15: Medical (plateau) | B15: =Medical!$C$28 -> 364000000
A16: Music (plays) | B16: =Music!$B$8 -> 100000000
A17: Core total (tx/mo) | B17: =SUM(B13:B16) -> 10964000000
A18: Web 2.0 payloads (if connected) | B18: ='Web 2.0'!$C$13+'Web 2.0'!$C$14+'Web 2.0'!$C$15 -> 7200000000000
A20: CONNECTOR ECONOMICS
A21: Core cross-shard tx / mo | B21: =B17*B6 -> 2192800000
A22: Core connector revenue / mo | B22: =B21*B5 -> 10964000
A23: Web 2.0 cross-shard tx / mo | B23: =B18*B8 -> 360000000000
A24: Web 2.0 connector revenue / mo | B24: =B23*B7 -> 180000000
A25: Total connector revenue / mo | B25: =B22+B24 -> 190964000
A26: Connector infra shards | B26: =CEILING((B21+B23)/B9,1) -> 12074
A27: Connector cost / mo | B27: =B26*B10 -> 50228516
A28: Connector margin | B28: =B25/B27 -> 3.8019041
A30: METCALFE: χ -> (n-1)/n grows the core tax base
A31: Connected shards n | B31: χ = (n-1)/n | C31: Core connector rev/mo
A32: 2 | B32: =(A32-1)/A32 -> 0.5 | C32: =$B$17*B32*$B$5 -> 27410000
A33: 5 | B33: =(A33-1)/A33 -> 0.8 | C33: =$B$17*B33*$B$5 -> 43856000
A34: 10 | B34: =(A34-1)/A34 -> 0.9 | C34: =$B$17*B34*$B$5 -> 49338000
A35: 50 | B35: =(A35-1)/A35 -> 0.98 | C35: =$B$17*B35*$B$5 -> 53723600
A36: 100 | B36: =(A36-1)/A36 -> 0.99 | C36: =$B$17*B36*$B$5 -> 54271800

Sheet Bandwidth
A1: Bandwidth — Media Egress (the per-byte exception)
A2: Egress = payload size x moves x rate. Negligible for text; dominant for imaging/lossless audio.
A4: PARAMETERS (linked from Assumptions)
A5: Internet egress ($/GB) | B5: =Assumptions!$B$43 -> 0.0085
A6: CDN / edge egress ($/GB) | B6: =Assumptions!$B$45 -> 0.04
A7: Inter-region egress ($/GB) | B7: =Assumptions!$B$44 -> 0.005
A8: Free egress tier (TB/mo) | B8: =Assumptions!$B$46 -> 10
A9: Note: first 10TB/mo free (per tenancy); Oracle reportedly moved to free egress across all regions Feb 2026. Figures below are marginal egress at scale (free tier negligible).
A11: EGRESS BY SCENARIO
A12: Scenario | B12: Payload (MB) | C12: Payloads/mo | D12: GB moved/mo | E12: Egress @ internet ($/mo) | F12: Egress @ CDN ($/mo) | G12: Egress/payload ($) | H12: % of sector rev
A13: Radiology (medical imaging) | B13: =Assumptions!$B$49 -> 250 | C13: =Medical!$B$7*Assumptions!$B$52 -> 36400000 | D13: =C13*B13/1024 -> 8886718.8 | E13: =D13*$B$5 -> 75537.109 | F13: =D13*$B$6 -> 355468.75 | G13: =E13/C13 -> 0.0020751953 | H13: =E13/Medical!$F$28 -> 0.010375977
A14: Music, compressed | B14: =Assumptions!$B$50 -> 4 | C14: =Music!$B$8 -> 100000000 | D14: =C14*B14/1024 -> 390625 | E14: =D14*$B$5 -> 3320.3125 | F14: =D14*$B$6 -> 15625 | G14: =E14/C14 -> 3.3203125e-05 | H14: =E14/Music!$B$20 -> 0.11067708
A15: Music, lossless / hi-res | B15: =Assumptions!$B$51 -> 40 | C15: =Music!$B$8 -> 100000000 | D15: =C15*B15/1024 -> 3906250 | E15: =D15*$B$5 -> 33203.125 | F15: =D15*$B$6 -> 156250 | G15: =E15/C15 -> 0.00033203125 | H15: =E15/Music!$B$20 -> 1.1067708
A16: Transactional (AI / fintech / EHR record) | B16: 0.003 | C16: =AI!$C$19 -> 10000000000 | D16: =C16*B16/1024 -> 29296.875 | E16: =D16*$B$5 -> 249.02344 | F16: =D16*$B$6 -> 1171.875 | G16: =E16/C16 -> 2.4902344e-08 | H16: negligible
A18: MUSIC: BANDWIDTH-INCLUSIVE BREAK-EVEN FEE
A19: Music shard+compute cost ($/mo) | B19: =Music!$B$13 -> 16640.224
A20: Break-even fee, compressed ($/play) | B20: =(B19+E14)/C14 -> 0.00019960537
A21: Break-even fee, lossless ($/play) | B21: =(B19+E15)/C15 -> 0.00049843349
A22: Current streaming fee ($/play) | B22: =Assumptions!$B$30 -> 0.0003
A23: Note: lossless exceeds the streaming fee -- needs a higher fee or edge caching.

Sheet Summary
A1: Summary — Five Sectors plus Web 2.0
A2: Break-even loads link live to each sector tab.
A4: Sector | B4: Revenue density | C4: Risk | D4: Boundedness | E4: Break-even load | F4: Strategic role
A5: AI | B5: $0.01 / tx | C5: low–mod | D5: none (machine vol.) | E5: =AI!$B$12 -> 0.016640224 | F5: anchor / growth
A6: Fintech | B6: ~$0.25 / tx | C6: high | D6: semi-bounded | E6: =Fintech!$B$11 -> 0.002080028 | F6: margin engine
A7: Medical | B7: high / patient | C7: highest | D7: hard cohort cap | E7: =Medical!$B$16 -> 0.04160056 | F7: cash-cow annuity
A8: Music | B8: $0.0003 / tx | C8: low | D8: roster-dependent | E8: ~near full | F8: cold-tail fill
A9: Web 2.0 | B9: ad-funded | C9: low–mod | D9: astronomical | E9: ~3 ads/day | F9: mass-market moat
A12: Rollout order: | B12: AI (anchor) → Fintech (margin) → Medical (annuity); Music = continuous fill; Web 2.0 = mass-market substrate via privacy wedge.
A14: Cross-cutting: | B14: CAC tab = wholesale (anchor) acquisition economics. Connector tab = the cross-shard interchange where the network monetises interoperability — the apex revenue layer at scale.
